Workbook

Sheet Day 1
A1: DISSOLVED OXYGEN LOG - DAY 1
A2: Date: | B2: 10.12.26 | C2: Weather: | D2: Sunny | H2: Recorded by: | I2: Gemina | O2: Location: | P2: Fishpond | V2: Reference: | W2: =Summary!$B$3 -> 13.5
A4: A. EVERY 20 SECONDS | H4: B. EVERY 5 MINUTES | O4: C. HOURLY 7AM-5PM | V4: D. CUSTOM
A5: # | B5: Elapsed | C5: DO mg/L | E5: % Sat | F5: Status | H5: # | I5: Elapsed | J5: DO mg/L | L5: % Sat | M5: Status | O5: # | P5: Time | Q5: DO mg/L | S5: % Sat | T5: Status | V5: # | W5: Time | X5: DO mg/L | Z5: % Sat | AA5: Status
A6: 1 | B6: 0:00 | C6: 13.5 | E6: =IF($C6="","",ROUND($C6/Summary!$B$3*100,1)) -> 100 | F6: =IF($C6="","",IF($C6<2,"LETHAL",IF($C6<4,"CRITICAL",IF($C6<5,"LOW",IF($C6<=8,"HEALTHY","SUPERSAT"))))) -> SUPERSAT | H6: 1 | I6: 0:00 | J6: 13.5 | L6: =IF($J6="","",ROUND($J6/Summary!$B$3*100,1)) -> 100 | M6: =IF($J6="","",IF($J6<2,"LETHAL",IF($J6<4,"CRITICAL",IF($J6<5,"LOW",IF($J6<=8,"HEALTHY","SUPERSAT"))))) -> SUPERSAT | O6: 1 | P6: 7:00 AM | Q6: 12.3 | S6: =IF($Q6="","",ROUND($Q6/Summary!$B$3*100,1)) -> 91.1 | T6: =IF($Q6="","",IF($Q6<2,"LETHAL",IF($Q6<4,"CRITICAL",IF($Q6<5,"LOW",IF($Q6<=8,"HEALTHY","SUPERSAT"))))) -> SUPERSAT | V6: 1 | Z6: =IF($X6="","",ROUND($X6/Summary!$B$3*100,1)) | AA6: =IF($X6="","",IF($X6<2,"LETHAL",IF($X6<4,"CRITICAL",IF($X6<5,"LOW",IF($X6<=8,"HEALTHY","SUPERSAT")))))
A7: 2 | B7: 0:20 | C7: 11.3 | E7: =IF($C7="","",ROUND($C7/Summary!$B$3*100,1)) -> 83.7 | F7: =IF($C7="","",IF($C7<2,"LETHAL",IF($C7<4,"CRITICAL",IF($C7<5,"LOW",IF($C7<=8,"HEALTHY","SUPERSAT"))))) -> SUPERSAT | H7: 2 | I7: 0:05 | J7: 11.7 | L7: =IF($J7="","",ROUND($J7/Summary!$B$3*100,1)) -> 86.7 | M7: =IF($J7="","",IF($J7<2,"LETHAL",IF($J7<4,"CRITICAL",IF($J7<5,"LOW",IF($J7<=8,"HEALTHY","SUPERSAT"))))) -> SUPERSAT | O7: 2 | P7: 8:00 AM | Q7: 12.6 | S7: =IF($Q7="","",ROUND($Q7/Summary!$B$3*100,1)) -> 93.3 | T7: =IF($Q7="","",IF($Q7<2,"LETHAL",IF($Q7<4,"CRITICAL",IF($Q7<5,"LOW",IF($Q7<=8,"HEALTHY","SUPERSAT"))))) -> SUPERSAT | V7: 2 | Z7: =IF($X7="","",ROUND($X7/Summary!$B$3*100,1)) | AA7: =IF($X7="","",IF($X7<2,"LETHAL",IF($X7<4,"CRITICAL",IF($X7<5,"LOW",IF($X7<=8,"HEALTHY","SUPERSAT")))))
A8: 3 | B8: 0:40 | C8: 11.5 | E8: =IF($C8="","",ROUND($C8/Summary!$B$3*100,1)) -> 85.2 | F8: =IF($C8="","",IF($C8<2,"LETHAL",IF($C8<4,"CRITICAL",IF($C8<5,"LOW",IF($C8<=8,"HEALTHY","SUPERSAT"))))) -> SUPERSAT | H8: 3 | I8: 0:10 | J8: 12.6 | L8: =IF($J8="","",ROUND($J8/Summary!$B$3*100,1)) -> 93.3 | M8: =IF($J8="","",IF($J8<2,"LETHAL",IF($J8<4,"CRITICAL",IF($J8<5,"LOW",IF($J8<=8,"HEALTHY","SUPERSAT"))))) -> SUPERSAT | O8: 3 | P8: 9:00 AM | Q8: 12.4 | S8: =IF($Q8="","",ROUND($Q8/Summary!$B$3*100,1)) -> 91.9 | T8: =IF($Q8="","",IF($Q8<2,"LETHAL",IF($Q8<4,"CRITICAL",IF($Q8<5,"LOW",IF($Q8<=8,"HEALTHY","SUPERSAT"))))) -> SUPERSAT | V8: 3 | Z8: =IF($X8="","",ROUND($X8/Summary!$B$3*100,1)) | AA8: =IF($X8="","",IF($X8<2,"LETHAL",IF($X8<4,"CRITICAL",IF($X8<5,"LOW",IF($X8<=8,"HEALTHY","SUPERSAT")))))
A9: 4 | B9: 1:00 | C9: 11.4 | E9: =IF($C9="","",ROUND($C9/Summary!$B$3*100,1)) -> 84.4 | F9: =IF($C9="","",IF($C9<2,"LETHAL",IF($C9<4,"CRITICAL",IF($C9<5,"LOW",IF($C9<=8,"HEALTHY","SUPERSAT"))))) -> SUPERSAT | H9: 4 | I9: 0:15 | J9: 12.9 | L9: =IF($J9="","",ROUND($J9/Summary!$B$3*100,1)) -> 95.6 | M9: =IF($J9="","",IF($J9<2,"LETHAL",IF($J9<4,"CRITICAL",IF($J9<5,"LOW",IF($J9<=8,"HEALTHY","SUPERSAT"))))) -> SUPERSAT | O9: 4 | P9: 10:00 AM | Q9: 12.7 | S9: =IF($Q9="","",ROUND($Q9/Summary!$B$3*100,1)) -> 94.1 | T9: =IF($Q9="","",IF($Q9<2,"LETHAL",IF($Q9<4,"CRITICAL",IF($Q9<5,"LOW",IF($Q9<=8,"HEALTHY","SUPERSAT"))))) -> SUPERSAT | V9: 4 | Z9: =IF($X9="","",ROUND($X9/Summary!$B$3*100,1)) | AA9: =IF($X9="","",IF($X9<2,"LETHAL",IF($X9<4,"CRITICAL",IF($X9<5,"LOW",IF($X9<=8,"HEALTHY","SUPERSAT")))))
A10: 5 | B10: 1:20 | C10: 11.6 | E10: =IF($C10="","",ROUND($C10/Summary!$B$3*100,1)) -> 85.9 | F10: =IF($C10="","",IF($C10<2,"LETHAL",IF($C10<4,"CRITICAL",IF($C10<5,"LOW",IF($C10<=8,"HEALTHY","SUPERSAT"))))) -> SUPERSAT | H10: 5 | I10: 0:20 | J10: 12.4 | L10: =IF($J10="","",ROUND($J10/Summary!$B$3*100,1)) -> 91.9 | M10: =IF($J10="","",IF($J10<2,"LETHAL",IF($J10<4,"CRITICAL",IF($J10<5,"LOW",IF($J10<=8,"HEALTHY","SUPERSAT"))))) -> SUPERSAT | O10: 5 | P10: 11:00 AM | Q10: 12.6 | S10: =IF($Q10="","",ROUND($Q10/Summary!$B$3*100,1)) -> 93.3 | T10: =IF($Q10="","",IF($Q10<2,"LETHAL",IF($Q10<4,"CRITICAL",IF($Q10<5,"LOW",IF($Q10<=8,"HEALTHY","SUPERSAT"))))) -> SUPERSAT | V10: 5 | Z10: =IF($X10="","",ROUND($X10/Summary!$B$3*100,1)) | AA10: =IF($X10="","",IF($X10<2,"LETHAL",IF($X10<4,"CRITICAL",IF($X10<5,"LOW",IF($X10<=8,"HEALTHY","SUPERSAT")))))
A11: 6 | B11: 1:40 | C11: 11.7 | E11: =IF($C11="","",ROUND($C11/Summary!$B$3*100,1)) -> 86.7 | F11: =IF($C11="","",IF($C11<2,"LETHAL",IF($C11<4,"CRITICAL",IF($C11<5,"LOW",IF($C11<=8,"HEALTHY","SUPERSAT"))))) -> SUPERSAT | H11: 6 | I11: 0:25 | J11: 12.5 | L11: =IF($J11="","",ROUND($J11/Summary!$B$3*100,1)) -> 92.6 | M11: =IF($J11="","",IF($J11<2,"LETHAL",IF($J11<4,"CRITICAL",IF($J11<5,"LOW",IF($J11<=8,"HEALTHY","SUPERSAT"))))) -> SUPERSAT | O11: 6 | P11: 12:00 NN | Q11: 12.4 | S11: =IF($Q11="","",ROUND($Q11/Summary!$B$3*100,1)) -> 91.9 | T11: =IF($Q11="","",IF($Q11<2,"LETHAL",IF($Q11<4,"CRITICAL",IF($Q11<5,"LOW",IF($Q11<=8,"HEALTHY","SUPERSAT"))))) -> SUPERSAT | V11: 6 | Z11: =IF($X11="","",ROUND($X11/Summary!$B$3*100,1)) | AA11: =IF($X11="","",IF($X11<2,"LETHAL",IF($X11<4,"CRITICAL",IF($X11<5,"LOW",IF($X11<=8,"HEALTHY","SUPERSAT")))))
A12: 7 | B12: 2:00 | C12: 11.7 | E12: =IF($C12="","",ROUND($C12/Summary!$B$3*100,1)) -> 86.7 | F12: =IF($C12="","",IF($C12<2,"LETHAL",IF($C12<4,"CRITICAL",IF($C12<5,"LOW",IF($C12<=8,"HEALTHY","SUPERSAT"))))) -> SUPERSAT | H12: 7 | I12: 0:30 | J12: 12.6 | L12: =IF($J12="","",ROUND($J12/Summary!$B$3*100,1)) -> 93.3 | M12: =IF($J12="","",IF($J12<2,"LETHAL",IF($J12<4,"CRITICAL",IF($J12<5,"LOW",IF($J12<=8,"HEALTHY","SUPERSAT"))))) -> SUPERSAT | O12: 7 | P12: 1:00 PM | Q12: 12.7 | S12: =IF($Q12="","",ROUND($Q12/Summary!$B$3*100,1)) -> 94.1 | T12: =IF($Q12="","",IF($Q12<2,"LETHAL",IF($Q12<4,"CRITICAL",IF($Q12<5,"LOW",IF($Q12<=8,"HEALTHY","SUPERSAT"))))) -> SUPERSAT | V12: 7 | Z12: =IF($X12="","",ROUND($X12/Summary!$B$3*100,1)) | AA12: =IF($X12="","",IF($X12<2,"LETHAL",IF($X12<4,"CRITICAL",IF($X12<5,"LOW",IF($X12<=8,"HEALTHY","SUPERSAT")))))
A13: 8 | B13: 2:20 | C13: 11.7 | E13: =IF($C13="","",ROUND($C13/Summary!$B$3*100,1)) -> 86.7 | F13: =IF($C13="","",IF($C13<2,"LETHAL",IF($C13<4,"CRITICAL",IF($C13<5,"LOW",IF($C13<=8,"HEALTHY","SUPERSAT"))))) -> SUPERSAT | H13: 8 | I13: 0:35 | J13: 12.6 | L13: =IF($J13="","",ROUND($J13/Summary!$B$3*100,1)) -> 93.3 | M13: =IF($J13="","",IF($J13<2,"LETHAL",IF($J13<4,"CRITICAL",IF($J13<5,"LOW",IF($J13<=8,"HEALTHY","SUPERSAT"))))) -> SUPERSAT | O13: 8 | P13: 2:00 PM | Q13: 12.6 | S13: =IF($Q13="","",ROUND($Q13/Summary!$B$3*100,1)) -> 93.3 | T13: =IF($Q13="","",IF($Q13<2,"LETHAL",IF($Q13<4,"CRITICAL",IF($Q13<5,"LOW",IF($Q13<=8,"HEALTHY","SUPERSAT"))))) -> SUPERSAT | V13: 8 | Z13: =IF($X13="","",ROUND($X13/Summary!$B$3*100,1)) | AA13: =IF($X13="","",IF($X13<2,"LETHAL",IF($X13<4,"CRITICAL",IF($X13<5,"LOW",IF($X13<=8,"HEALTHY","SUPERSAT")))))
A14: 9 | B14: 2:40 | C14: 11.8 | E14: =IF($C14="","",ROUND($C14/Summary!$B$3*100,1)) -> 87.4 | F14: =IF($C14="","",IF($C14<2,"LETHAL",IF($C14<4,"CRITICAL",IF($C14<5,"LOW",IF($C14<=8,"HEALTHY","SUPERSAT"))))) -> SUPERSAT | H14: 9 | I14: 0:40 | J14: 12.6 | L14: =IF($J14="","",ROUND($J14/Summary!$B$3*100,1)) -> 93.3 | M14: =IF($J14="","",IF($J14<2,"LETHAL",IF($J14<4,"CRITICAL",IF($J14<5,"LOW",IF($J14<=8,"HEALTHY","SUPERSAT"))))) -> SUPERSAT | O14: 9 | P14: 3:00 PM | Q14: 12.7 | S14: =IF($Q14="","",ROUND($Q14/Summary!$B$3*100,1)) -> 94.1 | T14: =IF($Q14="","",IF($Q14<2,"LETHAL",IF($Q14<4,"CRITICAL",IF($Q14<5,"LOW",IF($Q14<=8,"HEALTHY","SUPERSAT"))))) -> SUPERSAT | V14: 9 | Z14: =IF($X14="","",ROUND($X14/Summary!$B$3*100,1)) | AA14: =IF($X14="","",IF($X14<2,"LETHAL",IF($X14<4,"CRITICAL",IF($X14<5,"LOW",IF($X14<=8,"HEALTHY","SUPERSAT")))))
A15: 10 | B15: 3:00 | C15: 11.8 | E15: =IF($C15="","",ROUND($C15/Summary!$B$3*100,1)) -> 87.4 | F15: =IF($C15="","",IF($C15<2,"LETHAL",IF($C15<4,"CRITICAL",IF($C15<5,"LOW",IF($C15<=8,"HEALTHY","SUPERSAT"))))) -> SUPERSAT | H15: 10 | I15: 0:45 | J15: 12 | L15: =IF($J15="","",ROUND($J15/Summary!$B$3*100,1)) -> 88.9 | M15: =IF($J15="","",IF($J15<2,"LETHAL",IF($J15<4,"CRITICAL",IF($J15<5,"LOW",IF($J15<=8,"HEALTHY","SUPERSAT"))))) -> SUPERSAT | O15: 10 | P15: 4:00 PM | Q15: 11.5 | S15: =IF($Q15="","",ROUND($Q15/Summary!$B$3*100,1)) -> 85.2 | T15: =IF($Q15="","",IF($Q15<2,"LETHAL",IF($Q15<4,"CRITICAL",IF($Q15<5,"LOW",IF($Q15<=8,"HEALTHY","SUPERSAT"))))) -> SUPERSAT | V15: 10 | Z15: =IF($X15="","",ROUND($X15/Summary!$B$3*100,1)) | AA15: =IF($X15="","",IF($X15<2,"LETHAL",IF($X15<4,"CRITICAL",IF($X15<5,"LOW",IF($X15<=8,"HEALTHY","SUPERSAT")))))
A16: 11 | B16: 3:20 | C16: 11.7 | E16: =IF($C16="","",ROUND($C16/Summary!$B$3*100,1)) -> 86.7 | F16: =IF($C16="","",IF($C16<2,"LETHAL",IF($C16<4,"CRITICAL",IF($C16<5,"LOW",IF($C16<=8,"HEALTHY","SUPERSAT"))))) -> SUPERSAT | H16: 11 | I16: 0:50 | J16: 12.6 | L16: =IF($J16="","",ROUND($J16/Summary!$B$3*100,1)) -> 93.3 | M16: =IF($J16="","",IF($J16<2,"LETHAL",IF($J16<4,"CRITICAL",IF($J16<5,"LOW",IF($J16<=8,"HEALTHY","SUPERSAT"))))) -> SUPERSAT | O16: 11 | P16: 5:00 PM | Q16: 11.7 | S16: =IF($Q16="","",ROUND($Q16/Summary!$B$3*100,1)) -> 86.7 | T16: =IF($Q16="","",IF($Q16<2,"LETHAL",IF($Q16<4,"CRITICAL",IF($Q16<5,"LOW",IF($Q16<=8,"HEALTHY","SUPERSAT"))))) -> SUPERSAT | V16: 11 | Z16: =IF($X16="","",ROUND($X16/Summary!$B$3*100,1)) | AA16: =IF($X16="","",IF($X16<2,"LETHAL",IF($X16<4,"CRITICAL",IF($X16<5,"LOW",IF($X16<=8,"HEALTHY","SUPERSAT")))))
A17: 12 | B17: 3:40 | C17: 11.7 | E17: =IF($C17="","",ROUND($C17/Summary!$B$3*100,1)) -> 86.7 | F17: =IF($C17="","",IF($C17<2,"LETHAL",IF($C17<4,"CRITICAL",IF($C17<5,"LOW",IF($C17<=8,"HEALTHY","SUPERSAT"))))) -> SUPERSAT | H17: 12 | I17: 0:55 | J17: 12.3 | L17: =IF($J17="","",ROUND($J17/Summary!$B$3*100,1)) -> 91.1 | M17: =IF($J17="","",IF($J17<2,"LETHAL",IF($J17<4,"CRITICAL",IF($J17<5,"LOW",IF($J17<=8,"HEALTHY","SUPERSAT"))))) -> SUPERSAT | V17: 12 | Z17: =IF($X17="","",ROUND($X17/Summary!$B$3*100,1)) | AA17: =IF($X17="","",IF($X17<2,"LETHAL",IF($X17<4,"CRITICAL",IF($X17<5,"LOW",IF($X17<=8,"HEALTHY","SUPERSAT")))))
A18: 13 | B18: 4:00 | C18: 11.7 | E18: =IF($C18="","",ROUND($C18/Summary!$B$3*100,1)) -> 86.7 | F18: =IF($C18="","",IF($C18<2,"LETHAL",IF($C18<4,"CRITICAL",IF($C18<5,"LOW",IF($C18<=8,"HEALTHY","SUPERSAT"))))) -> SUPERSAT | H18: 13 | I18: 1:00 | J18: 12.1 | L18: =IF($J18="","",ROUND($J18/Summary!$B$3*100,1)) -> 89.6 | M18: =IF($J18="","",IF($J18<2,"LETHAL",IF($J18<4,"CRITICAL",IF($J18<5,"LOW",IF($J18<=8,"HEALTHY","SUPERSAT"))))) -> SUPERSAT | O18: STATISTICS | V18: 13 | Z18: =IF($X18="","",ROUND($X18/Summary!$B$3*100,1)) | AA18: =IF($X18="","",IF($X18<2,"LETHAL",IF($X18<4,"CRITICAL",IF($X18<5,"LOW",IF($X18<=8,"HEALTHY","SUPERSAT")))))
A19: 14 | B19: 4:20 | C19: 11.7 | E19: =IF($C19="","",ROUND($C19/Summary!$B$3*100,1)) -> 86.7 | F19: =IF($C19="","",IF($C19<2,"LETHAL",IF($C19<4,"CRITICAL",IF($C19<5,"LOW",IF($C19<=8,"HEALTHY","SUPERSAT"))))) -> SUPERSAT | H19: 14 | I19: 1:05 | J19: 12.7 | L19: =IF($J19="","",ROUND($J19/Summary!$B$3*100,1)) -> 94.1 | M19: =IF($J19="","",IF($J19<2,"LETHAL",IF($J19<4,"CRITICAL",IF($J19<5,"LOW",IF($J19<=8,"HEALTHY","SUPERSAT"))))) -> SUPERSAT | P19: Readings | Q19: =COUNT(Q6:Q16) -> 11 | V19: 14 | Z19: =IF($X19="","",ROUND($X19/Summary!$B$3*100,1)) | AA19: =IF($X19="","",IF($X19<2,"LETHAL",IF($X19<4,"CRITICAL",IF($X19<5,"LOW",IF($X19<=8,"HEALTHY","SUPERSAT")))))
A20: 15 | B20: 4:40 | C20: 11.7 | E20: =IF($C20="","",ROUND($C20/Summary!$B$3*100,1)) -> 86.7 | F20: =IF($C20="","",IF($C20<2,"LETHAL",IF($C20<4,"CRITICAL",IF($C20<5,"LOW",IF($C20<=8,"HEALTHY","SUPERSAT"))))) -> SUPERSAT | H20: 15 | I20: 1:10 | J20: 12.6 | L20: =IF($J20="","",ROUND($J20/Summary!$B$3*100,1)) -> 93.3 | M20: =IF($J20="","",IF($J20<2,"LETHAL",IF($J20<4,"CRITICAL",IF($J20<5,"LOW",IF($J20<=8,"HEALTHY","SUPERSAT"))))) -> SUPERSAT | P20: Mean | Q20: =IFERROR(AVERAGE(Q6:Q16),"") -> 12.381818 | V20: 15 | Z20: =IF($X20="","",ROUND($X20/Summary!$B$3*100,1)) | AA20: =IF($X20="","",IF($X20<2,"LETHAL",IF($X20<4,"CRITICAL",IF($X20<5,"LOW",IF($X20<=8,"HEALTHY","SUPERSAT")))))
A21: 16 | B21: 5:00 | C21: 11.7 | E21: =IF($C21="","",ROUND($C21/Summary!$B$3*100,1)) -> 86.7 | F21: =IF($C21="","",IF($C21<2,"LETHAL",IF($C21<4,"CRITICAL",IF($C21<5,"LOW",IF($C21<=8,"HEALTHY","SUPERSAT"))))) -> SUPERSAT | H21: 16 | I21: 1:15 | J21: 12.5 | L21: =IF($J21="","",ROUND($J21/Summary!$B$3*100,1)) -> 92.6 | M21: =IF($J21="","",IF($J21<2,"LETHAL",IF($J21<4,"CRITICAL",IF($J21<5,"LOW",IF($J21<=8,"HEALTHY","SUPERSAT"))))) -> SUPERSAT | P21: Std dev | Q21: =IFERROR(_xludf.STDEV.S(Q6:Q16),"") | V21: 16 | Z21: =IF($X21="","",ROUND($X21/Summary!$B$3*100,1)) | AA21: =IF($X21="","",IF($X21<2,"LETHAL",IF($X21<4,"CRITICAL",IF($X21<5,"LOW",IF($X21<=8,"HEALTHY","SUPERSAT")))))
A22: 17 | B22: 5:20 | C22: 12.2 | E22: =IF($C22="","",ROUND($C22/Summary!$B$3*100,1)) -> 90.4 | F22: =IF($C22="","",IF($C22<2,"LETHAL",IF($C22<4,"CRITICAL",IF($C22<5,"LOW",IF($C22<=8,"HEALTHY","SUPERSAT"))))) -> SUPERSAT | H22: 17 | I22: 1:20 | J22: 12.6 | L22: =IF($J22="","",ROUND($J22/Summary!$B$3*100,1)) -> 93.3 | M22: =IF($J22="","",IF($J22<2,"LETHAL",IF($J22<4,"CRITICAL",IF($J22<5,"LOW",IF($J22<=8,"HEALTHY","SUPERSAT"))))) -> SUPERSAT | P22: Minimum | Q22: =IFERROR(MIN(Q6:Q16),"") -> 11.5 | V22: 17 | Z22: =IF($X22="","",ROUND($X22/Summary!$B$3*100,1)) | AA22: =IF($X22="","",IF($X22<2,"LETHAL",IF($X22<4,"CRITICAL",IF($X22<5,"LOW",IF($X22<=8,"HEALTHY","SUPERSAT")))))
A23: 18 | B23: 5:40 | C23: 12.2 | E23: =IF($C23="","",ROUND($C23/Summary!$B$3*100,1)) -> 90.4 | F23: =IF($C23="","",IF($C23<2,"LETHAL",IF($C23<4,"CRITICAL",IF($C23<5,"LOW",IF($C23<=8,"HEALTHY","SUPERSAT"))))) -> SUPERSAT | H23: 18 | I23: 1:25 | J23: 12.6 | L23: =IF($J23="","",ROUND($J23/Summary!$B$3*100,1)) -> 93.3 | M23: =IF($J23="","",IF($J23<2,"LETHAL",IF($J23<4,"CRITICAL",IF($J23<5,"LOW",IF($J23<=8,"HEALTHY","SUPERSAT"))))) -> SUPERSAT | P23: Maximum | Q23: =IFERROR(MAX(Q6:Q16),"") -> 12.7 | V23: 18 | Z23: =IF($X23="","",ROUND($X23/Summary!$B$3*100,1)) | AA23: =IF($X23="","",IF($X23<2,"LETHAL",IF($X23<4,"CRITICAL",IF($X23<5,"LOW",IF($X23<=8,"HEALTHY","SUPERSAT")))))
A24: 19 | B24: 6:00 | C24: 12.2 | E24: =IF($C24="","",ROUND($C24/Summary!$B$3*100,1)) -> 90.4 | F24: =IF($C24="","",IF($C24<2,"LETHAL",IF($C24<4,"CRITICAL",IF($C24<5,"LOW",IF($C24<=8,"HEALTHY","SUPERSAT"))))) -> SUPERSAT | H24: 19 | I24: 1:30 | J24: 12.3 | L24: =IF($J24="","",ROUND($J24/Summary!$B$3*100,1)) -> 91.1 | M24: =IF($J24="","",IF($J24<2,"LETHAL",IF($J24<4,"CRITICAL",IF($J24<5,"LOW",IF($J24<=8,"HEALTHY","SUPERSAT"))))) -> SUPERSAT | P24: Range | Q24: =IF(COUNT(Q6:Q16)=0,"",MAX(Q6:Q16)-MIN(Q6:Q16)) -> 1.2 | V24: 19 | Z24: =IF($X24="","",ROUND($X24/Summary!$B$3*100,1)) | AA24: =IF($X24="","",IF($X24<2,"LETHAL",IF($X24<4,"CRITICAL",IF($X24<5,"LOW",IF($X24<=8,"HEALTHY","SUPERSAT")))))
A25: 20 | B25: 6:20 | C25: 12.4 | E25: =IF($C25="","",ROUND($C25/Summary!$B$3*100,1)) -> 91.9 | F25: =IF($C25="","",IF($C25<2,"LETHAL",IF($C25<4,"CRITICAL",IF($C25<5,"LOW",IF($C25<=8,"HEALTHY","SUPERSAT"))))) -> SUPERSAT | H25: 20 | I25: 1:35 | J25: 12.1 | L25: =IF($J25="","",ROUND($J25/Summary!$B$3*100,1)) -> 89.6 | M25: =IF($J25="","",IF($J25<2,"LETHAL",IF($J25<4,"CRITICAL",IF($J25<5,"LOW",IF($J25<=8,"HEALTHY","SUPERSAT"))))) -> SUPERSAT | P25: Mean % sat | Q25: =IFERROR(AVERAGE(S6:S16),"") -> 91.727273 | V25: 20 | Z25: =IF($X25="","",ROUND($X25/Summary!$B$3*100,1)) | AA25: =IF($X25="","",IF($X25<2,"LETHAL",IF($X25<4,"CRITICAL",IF($X25<5,"LOW",IF($X25<=8,"HEALTHY","SUPERSAT")))))
A26: 21 | B26: 6:40 | C26: 12.3 | E26: =IF($C26="","",ROUND($C26/Summary!$B$3*100,1)) -> 91.1 | F26: =IF($C26="","",IF($C26<2,"LETHAL",IF($C26<4,"CRITICAL",IF($C26<5,"LOW",IF($C26<=8,"HEALTHY","SUPERSAT"))))) -> SUPERSAT | H26: 21 | I26: 1:40 | J26: 12.1 | L26: =IF($J26="","",ROUND($J26/Summary!$B$3*100,1)) -> 89.6 | M26: =IF($J26="","",IF($J26<2,"LETHAL",IF($J26<4,"CRITICAL",IF($J26<5,"LOW",IF($J26<=8,"HEALTHY","SUPERSAT"))))) -> SUPERSAT | V26: 21 | Z26: =IF($X26="","",ROUND($X26/Summary!$B$3*100,1)) | AA26: =IF($X26="","",IF($X26<2,"LETHAL",IF($X26<4,"CRITICAL",IF($X26<5,"LOW",IF($X26<=8,"HEALTHY","SUPERSAT")))))
A27: 22 | B27: 7:00 | C27: 12.3 | E27: =IF($C27="","",ROUND($C27/Summary!$B$3*100,1)) -> 91.1 | F27: =IF($C27="","",IF($C27<2,"LETHAL",IF($C27<4,"CRITICAL",IF($C27<5,"LOW",IF($C27<=8,"HEALTHY","SUPERSAT"))))) -> SUPERSAT | H27: 22 | I27: 1:45 | J27: 12.5 | L27: =IF($J27="","",ROUND($J27/Summary!$B$3*100,1)) -> 92.6 | M27: =IF($J27="","",IF($J27<2,"LETHAL",IF($J27<4,"CRITICAL",IF($J27<5,"LOW",IF($J27<=8,"HEALTHY","SUPERSAT"))))) -> SUPERSAT | V27: 22 | Z27: =IF($X27="","",ROUND($X27/Summary!$B$3*100,1)) | AA27: =IF($X27="","",IF($X27<2,"LETHAL",IF($X27<4,"CRITICAL",IF($X27<5,"LOW",IF($X27<=8,"HEALTHY","SUPERSAT")))))
A28: 23 | B28: 7:20 | C28: 12.5 | E28: =IF($C28="","",ROUND($C28/Summary!$B$3*100,1)) -> 92.6 | F28: =IF($C28="","",IF($C28<2,"LETHAL",IF($C28<4,"CRITICAL",IF($C28<5,"LOW",IF($C28<=8,"HEALTHY","SUPERSAT"))))) -> SUPERSAT | H28: 23 | I28: 1:50 | J28: 12.6 | L28: =IF($J28="","",ROUND($J28/Summary!$B$3*100,1)) -> 93.3 | M28: =IF($J28="","",IF($J28<2,"LETHAL",IF($J28<4,"CRITICAL",IF($J28<5,"LOW",IF($J28<=8,"HEALTHY","SUPERSAT"))))) -> SUPERSAT | V28: 23 | Z28: =IF($X28="","",ROUND($X28/Summary!$B$3*100,1)) | AA28: =IF($X28="","",IF($X28<2,"LETHAL",IF($X28<4,"CRITICAL",IF($X28<5,"LOW",IF($X28<=8,"HEALTHY","SUPERSAT")))))
A29: 24 | B29: 7:40 | C29: 12.3 | E29: =IF($C29="","",ROUND($C29/Summary!$B$3*100,1)) -> 91.1 | F29: =IF($C29="","",IF($C29<2,"LETHAL",IF($C29<4,"CRITICAL",IF($C29<5,"LOW",IF($C29<=8,"HEALTHY","SUPERSAT"))))) -> SUPERSAT | H29: 24 | I29: 1:55 | J29: 12.3 | L29: =IF($J29="","",ROUND($J29/Summary!$B$3*100,1)) -> 91.1 | M29: =IF($J29="","",IF($J29<2,"LETHAL",IF($J29<4,"CRITICAL",IF($J29<5,"LOW",IF($J29<=8,"HEALTHY","SUPERSAT"))))) -> SUPERSAT | V29: 24 | Z29: =IF($X29="","",ROUND($X29/Summary!$B$3*100,1)) | AA29: =IF($X29="","",IF($X29<2,"LETHAL",IF($X29<4,"CRITICAL",IF($X29<5,"LOW",IF($X29<=8,"HEALTHY","SUPERSAT")))))
A30: 25 | B30: 8:00 | C30: 12.5 | E30: =IF($C30="","",ROUND($C30/Summary!$B$3*100,1)) -> 92.6 | F30: =IF($C30="","",IF($C30<2,"LETHAL",IF($C30<4,"CRITICAL",IF($C30<5,"LOW",IF($C30<=8,"HEALTHY","SUPERSAT"))))) -> SUPERSAT | H30: 25 | I30: 2:00 | J30: 12.6 | L30: =IF($J30="","",ROUND($J30/Summary!$B$3*100,1)) -> 93.3 | M30: =IF($J30="","",IF($J30<2,"LETHAL",IF($J30<4,"CRITICAL",IF($J30<5,"LOW",IF($J30<=8,"HEALTHY","SUPERSAT"))))) -> SUPERSAT | V30: 25 | Z30: =IF($X30="","",ROUND($X30/Summary!$B$3*100,1)) | AA30: =IF($X30="","",IF($X30<2,"LETHAL",IF($X30<4,"CRITICAL",IF($X30<5,"LOW",IF($X30<=8,"HEALTHY","SUPERSAT")))))
A31: 26 | B31: 8:20 | C31: 12.5 | E31: =IF($C31="","",ROUND($C31/Summary!$B$3*100,1)) -> 92.6 | F31: =IF($C31="","",IF($C31<2,"LETHAL",IF($C31<4,"CRITICAL",IF($C31<5,"LOW",IF($C31<=8,"HEALTHY","SUPERSAT"))))) -> SUPERSAT | H31: 26 | I31: 2:05 | J31: 12.5 | L31: =IF($J31="","",ROUND($J31/Summary!$B$3*100,1)) -> 92.6 | M31: =IF($J31="","",IF($J31<2,"LETHAL",IF($J31<4,"CRITICAL",IF($J31<5,"LOW",IF($J31<=8,"HEALTHY","SUPERSAT"))))) -> SUPERSAT | V31: 26 | Z31: =IF($X31="","",ROUND($X31/Summary!$B$3*100,1)) | AA31: =IF($X31="","",IF($X31<2,"LETHAL",IF($X31<4,"CRITICAL",IF($X31<5,"LOW",IF($X31<=8,"HEALTHY","SUPERSAT")))))
A32: 27 | B32: 8:40 | C32: 12.7 | E32: =IF($C32="","",ROUND($C32/Summary!$B$3*100,1)) -> 94.1 | F32: =IF($C32="","",IF($C32<2,"LETHAL",IF($C32<4,"CRITICAL",IF($C32<5,"LOW",IF($C32<=8,"HEALTHY","SUPERSAT"))))) -> SUPERSAT | H32: 27 | I32: 2:10 | J32: 12.3 | L32: =IF($J32="","",ROUND($J32/Summary!$B$3*100,1)) -> 91.1 | M32: =IF($J32="","",IF($J32<2,"LETHAL",IF($J32<4,"CRITICAL",IF($J32<5,"LOW",IF($J32<=8,"HEALTHY","SUPERSAT"))))) -> SUPERSAT | V32: 27 | Z32: =IF($X32="","",ROUND($X32/Summary!$B$3*100,1)) | AA32: =IF($X32="","",IF($X32<2,"LETHAL",IF($X32<4,"CRITICAL",IF($X32<5,"LOW",IF($X32<=8,"HEALTHY","SUPERSAT")))))
A33: 28 | B33: 9:00 | C33: 12.7 | E33: =IF($C33="","",ROUND($C33/Summary!$B$3*100,1)) -> 94.1 | F33: =IF($C33="","",IF($C33<2,"LETHAL",IF($C33<4,"CRITICAL",IF($C33<5,"LOW",IF($C33<=8,"HEALTHY","SUPERSAT"))))) -> SUPERSAT | H33: 28 | I33: 2:15 | J33: 12.2 | L33: =IF($J33="","",ROUND($J33/Summary!$B$3*100,1)) -> 90.4 | M33: =IF($J33="","",IF($J33<2,"LETHAL",IF($J33<4,"CRITICAL",IF($J33<5,"LOW",IF($J33<=8,"HEALTHY","SUPERSAT"))))) -> SUPERSAT | V33: 28 | Z33: =IF($X33="","",ROUND($X33/Summary!$B$3*100,1)) | AA33: =IF($X33="","",IF($X33<2,"LETHAL",IF($X33<4,"CRITICAL",IF($X33<5,"LOW",IF($X33<=8,"HEALTHY","SUPERSAT")))))
A34: 29 | B34: 9:20 | C34: 12.7 | E34: =IF($C34="","",ROUND($C34/Summary!$B$3*100,1)) -> 94.1 | F34: =IF($C34="","",IF($C34<2,"LETHAL",IF($C34<4,"CRITICAL",IF($C34<5,"LOW",IF($C34<=8,"HEALTHY","SUPERSAT"))))) -> SUPERSAT | H34: 29 | I34: 2:20 | J34: 12.1 | L34: =IF($J34="","",ROUND($J34/Summary!$B$3*100,1)) -> 89.6 | M34: =IF($J34="","",IF($J34<2,"LETHAL",IF($J34<4,"CRITICAL",IF($J34<5,"LOW",IF($J34<=8,"HEALTHY","SUPERSAT"))))) -> SUPERSAT | V34: 29 | Z34: =IF($X34="","",ROUND($X34/Summary!$B$3*100,1)) | AA34: =IF($X34="","",IF($X34<2,"LETHAL",IF($X34<4,"CRITICAL",IF($X34<5,"LOW",IF($X34<=8,"HEALTHY","SUPERSAT")))))
A35: 30 | B35: 9:40 | C35: 12.7 | E35: =IF($C35="","",ROUND($C35/Summary!$B$3*100,1)) -> 94.1 | F35: =IF($C35="","",IF($C35<2,"LETHAL",IF($C35<4,"CRITICAL",IF($C35<5,"LOW",IF($C35<=8,"HEALTHY","SUPERSAT"))))) -> SUPERSAT | H35: 30 | I35: 2:25 | J35: 12 | L35: =IF($J35="","",ROUND($J35/Summary!$B$3*100,1)) -> 88.9 | M35: =IF($J35="","",IF($J35<2,"LETHAL",IF($J35<4,"CRITICAL",IF($J35<5,"LOW",IF($J35<=8,"HEALTHY","SUPERSAT"))))) -> SUPERSAT | V35: 30 | Z35: =IF($X35="","",ROUND($X35/Summary!$B$3*100,1)) | AA35: =IF($X35="","",IF($X35<2,"LETHAL",IF($X35<4,"CRITICAL",IF($X35<5,"LOW",IF($X35<=8,"HEALTHY","SUPERSAT")))))
A36: 31 | B36: 10:00 | C36: 12.6 | E36: =IF($C36="","",ROUND($C36/Summary!$B$3*100,1)) -> 93.3 | F36: =IF($C36="","",IF($C36<2,"LETHAL",IF($C36<4,"CRITICAL",IF($C36<5,"LOW",IF($C36<=8,"HEALTHY","SUPERSAT"))))) -> SUPERSAT | H36: 31 | I36: 2:30 | J36: 12 | L36: =IF($J36="","",ROUND($J36/Summary!$B$3*100,1)) -> 88.9 | M36: =IF($J36="","",IF($J36<2,"LETHAL",IF($J36<4,"CRITICAL",IF($J36<5,"LOW",IF($J36<=8,"HEALTHY","SUPERSAT"))))) -> SUPERSAT | V36: 31 | Z36: =IF($X36="","",ROUND($X36/Summary!$B$3*100,1)) | AA36: =IF($X36="","",IF($X36<2,"LETHAL",IF($X36<4,"CRITICAL",IF($X36<5,"LOW",IF($X36<=8,"HEALTHY","SUPERSAT")))))
A37: 32 | B37: 10:20 | C37: 12.6 | E37: =IF($C37="","",ROUND($C37/Summary!$B$3*100,1)) -> 93.3 | F37: =IF($C37="","",IF($C37<2,"LETHAL",IF($C37<4,"CRITICAL",IF($C37<5,"LOW",IF($C37<=8,"HEALTHY","SUPERSAT"))))) -> SUPERSAT | H37: 32 | I37: 2:35 | J37: 12.7 | L37: =IF($J37="","",ROUND($J37/Summary!$B$3*100,1)) -> 94.1 | M37: =IF($J37="","",IF($J37<2,"LETHAL",IF($J37<4,"CRITICAL",IF($J37<5,"LOW",IF($J37<=8,"HEALTHY","SUPERSAT"))))) -> SUPERSAT | V37: 32 | Z37: =IF($X37="","",ROUND($X37/Summary!$B$3*100,1)) | AA37: =IF($X37="","",IF($X37<2,"LETHAL",IF($X37<4,"CRITICAL",IF($X37<5,"LOW",IF($X37<=8,"HEALTHY","SUPERSAT")))))
... A55: 50 | B55: 16:20 | C55: 12.6 | E55: =IF($C55="","",ROUND($C55/Summary!$B$3*100,1)) -> 93.3 | F55: =IF($C55="","",IF($C55<2,"LETHAL",IF($C55<4,"CRITICAL",IF($C55<5,"LOW",IF($C55<=8,"HEALTHY","SUPERSAT"))))) -> SUPERSAT | H55: 50 | I55: 4:05 | J55: 12.7 | L55: =IF($J55="","",ROUND($J55/Summary!$B$3*100,1)) -> 94.1 | M55: =IF($J55="","",IF($J55<2,"LETHAL",IF($J55<4,"CRITICAL",IF($J55<5,"LOW",IF($J55<=8,"HEALTHY","SUPERSAT"))))) -> SUPERSAT | V55: 50 | Z55: =IF($X55="","",ROUND($X55/Summary!$B$3*100,1)) | AA55: =IF($X55="","",IF($X55<2,"LETHAL",IF($X55<4,"CRITICAL",IF($X55<5,"LOW",IF($X55<=8,"HEALTHY","SUPERSAT")))))
A57: STATISTICS | V57: STATISTICS
B58: Readings | C58: =COUNT(C6:C55) -> 50 | I58: Readings | J58: =COUNT(J6:J55) -> 50 | W58: Readings | X58: =COUNT(X6:X55) -> 0
B59: Mean | C59: =IFERROR(AVERAGE(C6:C55),"") -> 12.278 | I59: Mean | J59: =IFERROR(AVERAGE(J6:J55),"") -> 12.466 | W59: Mean | X59: =IFERROR(AVERAGE(X6:X55),"")
...

Sheet Day 2
A1: DISSOLVED OXYGEN LOG - DAY 2
A2: Date: | B2: 10.13.2026 | C2: Weather: | D2: Haze/Cloudy | H2: Recorded by: | J2: Gemina | O2: Location: | P2: Fishpond | V2: Reference: | W2: =Summary!$B$3 -> 13.5
D3: Rained Last Night
A4: A. EVERY 20 SECONDS | H4: B. EVERY 5 MINUTES | O4: C. HOURLY 7AM-5PM | V4: D. CUSTOM
A5: # | B5: Elapsed | C5: DO mg/L | E5: % Sat | F5: Status | H5: # | I5: Elapsed | J5: DO mg/L | L5: % Sat | M5: Status | O5: # | P5: Time | Q5: DO mg/L | S5: % Sat | T5: Status | V5: # | W5: Time | X5: DO mg/L | Z5: % Sat | AA5: Status
A6: 1 | B6: 0:00 | C6: 3.2 | E6: =IF($C6="","",ROUND($C6/Summary!$B$3*100,1)) -> 23.7 | F6: =IF($C6="","",IF($C6<2,"LETHAL",IF($C6<4,"CRITICAL",IF($C6<5,"LOW",IF($C6<=8,"HEALTHY","SUPERSAT"))))) -> CRITICAL | H6: 1 | I6: 0:00 | J6: 3.2 | L6: =IF($J6="","",ROUND($J6/Summary!$B$3*100,1)) -> 23.7 | M6: =IF($J6="","",IF($J6<2,"LETHAL",IF($J6<4,"CRITICAL",IF($J6<5,"LOW",IF($J6<=8,"HEALTHY","SUPERSAT"))))) -> CRITICAL | O6: 1 | P6: 7:00 AM | Q6: 3.3 | S6: =IF($Q6="","",ROUND($Q6/Summary!$B$3*100,1)) -> 24.4 | T6: =IF($Q6="","",IF($Q6<2,"LETHAL",IF($Q6<4,"CRITICAL",IF($Q6<5,"LOW",IF($Q6<=8,"HEALTHY","SUPERSAT"))))) -> CRITICAL | V6: 1 | Z6: =IF($X6="","",ROUND($X6/Summary!$B$3*100,1)) | AA6: =IF($X6="","",IF($X6<2,"LETHAL",IF($X6<4,"CRITICAL",IF($X6<5,"LOW",IF($X6<=8,"HEALTHY","SUPERSAT")))))
A7: 2 | B7: 0:20 | C7: 3.3 | E7: =IF($C7="","",ROUND($C7/Summary!$B$3*100,1)) -> 24.4 | F7: =IF($C7="","",IF($C7<2,"LETHAL",IF($C7<4,"CRITICAL",IF($C7<5,"LOW",IF($C7<=8,"HEALTHY","SUPERSAT"))))) -> CRITICAL | H7: 2 | I7: 0:05 | J7: 3.5 | L7: =IF($J7="","",ROUND($J7/Summary!$B$3*100,1)) -> 25.9 | M7: =IF($J7="","",IF($J7<2,"LETHAL",IF($J7<4,"CRITICAL",IF($J7<5,"LOW",IF($J7<=8,"HEALTHY","SUPERSAT"))))) -> CRITICAL | O7: 2 | P7: 8:00 AM | Q7: 5.5 | S7: =IF($Q7="","",ROUND($Q7/Summary!$B$3*100,1)) -> 40.7 | T7: =IF($Q7="","",IF($Q7<2,"LETHAL",IF($Q7<4,"CRITICAL",IF($Q7<5,"LOW",IF($Q7<=8,"HEALTHY","SUPERSAT"))))) -> HEALTHY | V7: 2 | Z7: =IF($X7="","",ROUND($X7/Summary!$B$3*100,1)) | AA7: =IF($X7="","",IF($X7<2,"LETHAL",IF($X7<4,"CRITICAL",IF($X7<5,"LOW",IF($X7<=8,"HEALTHY","SUPERSAT")))))
A8: 3 | B8: 0:40 | C8: 3.4 | E8: =IF($C8="","",ROUND($C8/Summary!$B$3*100,1)) -> 25.2 | F8: =IF($C8="","",IF($C8<2,"LETHAL",IF($C8<4,"CRITICAL",IF($C8<5,"LOW",IF($C8<=8,"HEALTHY","SUPERSAT"))))) -> CRITICAL | H8: 3 | I8: 0:10 | J8: 4.3 | L8: =IF($J8="","",ROUND($J8/Summary!$B$3*100,1)) -> 31.9 | M8: =IF($J8="","",IF($J8<2,"LETHAL",IF($J8<4,"CRITICAL",IF($J8<5,"LOW",IF($J8<=8,"HEALTHY","SUPERSAT"))))) -> LOW | O8: 3 | P8: 9:00 AM | Q8: 5.8 | S8: =IF($Q8="","",ROUND($Q8/Summary!$B$3*100,1)) -> 43 | T8: =IF($Q8="","",IF($Q8<2,"LETHAL",IF($Q8<4,"CRITICAL",IF($Q8<5,"LOW",IF($Q8<=8,"HEALTHY","SUPERSAT"))))) -> HEALTHY | V8: 3 | Z8: =IF($X8="","",ROUND($X8/Summary!$B$3*100,1)) | AA8: =IF($X8="","",IF($X8<2,"LETHAL",IF($X8<4,"CRITICAL",IF($X8<5,"LOW",IF($X8<=8,"HEALTHY","SUPERSAT")))))
A9: 4 | B9: 1:00 | C9: 3.6 | E9: =IF($C9="","",ROUND($C9/Summary!$B$3*100,1)) -> 26.7 | F9: =IF($C9="","",IF($C9<2,"LETHAL",IF($C9<4,"CRITICAL",IF($C9<5,"LOW",IF($C9<=8,"HEALTHY","SUPERSAT"))))) -> CRITICAL | H9: 4 | I9: 0:15 | J9: 5.5 | L9: =IF($J9="","",ROUND($J9/Summary!$B$3*100,1)) -> 40.7 | M9: =IF($J9="","",IF($J9<2,"LETHAL",IF($J9<4,"CRITICAL",IF($J9<5,"LOW",IF($J9<=8,"HEALTHY","SUPERSAT"))))) -> HEALTHY | O9: 4 | P9: 10:00 AM | Q9: 5.8 | S9: =IF($Q9="","",ROUND($Q9/Summary!$B$3*100,1)) -> 43 | T9: =IF($Q9="","",IF($Q9<2,"LETHAL",IF($Q9<4,"CRITICAL",IF($Q9<5,"LOW",IF($Q9<=8,"HEALTHY","SUPERSAT"))))) -> HEALTHY | V9: 4 | Z9: =IF($X9="","",ROUND($X9/Summary!$B$3*100,1)) | AA9: =IF($X9="","",IF($X9<2,"LETHAL",IF($X9<4,"CRITICAL",IF($X9<5,"LOW",IF($X9<=8,"HEALTHY","SUPERSAT")))))
A10: 5 | B10: 1:20 | C10: 3.7 | E10: =IF($C10="","",ROUND($C10/Summary!$B$3*100,1)) -> 27.4 | F10: =IF($C10="","",IF($C10<2,"LETHAL",IF($C10<4,"CRITICAL",IF($C10<5,"LOW",IF($C10<=8,"HEALTHY","SUPERSAT"))))) -> CRITICAL | H10: 5 | I10: 0:20 | J10: 5.5 | L10: =IF($J10="","",ROUND($J10/Summary!$B$3*100,1)) -> 40.7 | M10: =IF($J10="","",IF($J10<2,"LETHAL",IF($J10<4,"CRITICAL",IF($J10<5,"LOW",IF($J10<=8,"HEALTHY","SUPERSAT"))))) -> HEALTHY | O10: 5 | P10: 11:00 AM | Q10: 5.4 | S10: =IF($Q10="","",ROUND($Q10/Summary!$B$3*100,1)) -> 40 | T10: =IF($Q10="","",IF($Q10<2,"LETHAL",IF($Q10<4,"CRITICAL",IF($Q10<5,"LOW",IF($Q10<=8,"HEALTHY","SUPERSAT"))))) -> HEALTHY | V10: 5 | Z10: =IF($X10="","",ROUND($X10/Summary!$B$3*100,1)) | AA10: =IF($X10="","",IF($X10<2,"LETHAL",IF($X10<4,"CRITICAL",IF($X10<5,"LOW",IF($X10<=8,"HEALTHY","SUPERSAT")))))
A11: 6 | B11: 1:40 | C11: 3.6 | E11: =IF($C11="","",ROUND($C11/Summary!$B$3*100,1)) -> 26.7 | F11: =IF($C11="","",IF($C11<2,"LETHAL",IF($C11<4,"CRITICAL",IF($C11<5,"LOW",IF($C11<=8,"HEALTHY","SUPERSAT"))))) -> CRITICAL | H11: 6 | I11: 0:25 | J11: 5.4 | L11: =IF($J11="","",ROUND($J11/Summary!$B$3*100,1)) -> 40 | M11: =IF($J11="","",IF($J11<2,"LETHAL",IF($J11<4,"CRITICAL",IF($J11<5,"LOW",IF($J11<=8,"HEALTHY","SUPERSAT"))))) -> HEALTHY | O11: 6 | P11: 12:00 NN | Q11: 5.5 | S11: =IF($Q11="","",ROUND($Q11/Summary!$B$3*100,1)) -> 40.7 | T11: =IF($Q11="","",IF($Q11<2,"LETHAL",IF($Q11<4,"CRITICAL",IF($Q11<5,"LOW",IF($Q11<=8,"HEALTHY","SUPERSAT"))))) -> HEALTHY | V11: 6 | Z11: =IF($X11="","",ROUND($X11/Summary!$B$3*100,1)) | AA11: =IF($X11="","",IF($X11<2,"LETHAL",IF($X11<4,"CRITICAL",IF($X11<5,"LOW",IF($X11<=8,"HEALTHY","SUPERSAT")))))
A12: 7 | B12: 2:00 | C12: 3.7 | E12: =IF($C12="","",ROUND($C12/Summary!$B$3*100,1)) -> 27.4 | F12: =IF($C12="","",IF($C12<2,"LETHAL",IF($C12<4,"CRITICAL",IF($C12<5,"LOW",IF($C12<=8,"HEALTHY","SUPERSAT"))))) -> CRITICAL | H12: 7 | I12: 0:30 | J12: 5.5 | L12: =IF($J12="","",ROUND($J12/Summary!$B$3*100,1)) -> 40.7 | M12: =IF($J12="","",IF($J12<2,"LETHAL",IF($J12<4,"CRITICAL",IF($J12<5,"LOW",IF($J12<=8,"HEALTHY","SUPERSAT"))))) -> HEALTHY | O12: 7 | P12: 1:00 PM | Q12: 5.4 | S12: =IF($Q12="","",ROUND($Q12/Summary!$B$3*100,1)) -> 40 | T12: =IF($Q12="","",IF($Q12<2,"LETHAL",IF($Q12<4,"CRITICAL",IF($Q12<5,"LOW",IF($Q12<=8,"HEALTHY","SUPERSAT"))))) -> HEALTHY | V12: 7 | Z12: =IF($X12="","",ROUND($X12/Summary!$B$3*100,1)) | AA12: =IF($X12="","",IF($X12<2,"LETHAL",IF($X12<4,"CRITICAL",IF($X12<5,"LOW",IF($X12<=8,"HEALTHY","SUPERSAT")))))
A13: 8 | B13: 2:20 | C13: 3.8 | E13: =IF($C13="","",ROUND($C13/Summary!$B$3*100,1)) -> 28.1 | F13: =IF($C13="","",IF($C13<2,"LETHAL",IF($C13<4,"CRITICAL",IF($C13<5,"LOW",IF($C13<=8,"HEALTHY","SUPERSAT"))))) -> CRITICAL | H13: 8 | I13: 0:35 | J13: 5.5 | L13: =IF($J13="","",ROUND($J13/Summary!$B$3*100,1)) -> 40.7 | M13: =IF($J13="","",IF($J13<2,"LETHAL",IF($J13<4,"CRITICAL",IF($J13<5,"LOW",IF($J13<=8,"HEALTHY","SUPERSAT"))))) -> HEALTHY | O13: 8 | P13: 2:00 PM | Q13: 5.4 | S13: =IF($Q13="","",ROUND($Q13/Summary!$B$3*100,1)) -> 40 | T13: =IF($Q13="","",IF($Q13<2,"LETHAL",IF($Q13<4,"CRITICAL",IF($Q13<5,"LOW",IF($Q13<=8,"HEALTHY","SUPERSAT"))))) -> HEALTHY | V13: 8 | Z13: =IF($X13="","",ROUND($X13/Summary!$B$3*100,1)) | AA13: =IF($X13="","",IF($X13<2,"LETHAL",IF($X13<4,"CRITICAL",IF($X13<5,"LOW",IF($X13<=8,"HEALTHY","SUPERSAT")))))
A14: 9 | B14: 2:40 | C14: 3.4 | E14: =IF($C14="","",ROUND($C14/Summary!$B$3*100,1)) -> 25.2 | F14: =IF($C14="","",IF($C14<2,"LETHAL",IF($C14<4,"CRITICAL",IF($C14<5,"LOW",IF($C14<=8,"HEALTHY","SUPERSAT"))))) -> CRITICAL | H14: 9 | I14: 0:40 | J14: 5.6 | L14: =IF($J14="","",ROUND($J14/Summary!$B$3*100,1)) -> 41.5 | M14: =IF($J14="","",IF($J14<2,"LETHAL",IF($J14<4,"CRITICAL",IF($J14<5,"LOW",IF($J14<=8,"HEALTHY","SUPERSAT"))))) -> HEALTHY | O14: 9 | P14: 3:00 PM | Q14: 5.3 | S14: =IF($Q14="","",ROUND($Q14/Summary!$B$3*100,1)) -> 39.3 | T14: =IF($Q14="","",IF($Q14<2,"LETHAL",IF($Q14<4,"CRITICAL",IF($Q14<5,"LOW",IF($Q14<=8,"HEALTHY","SUPERSAT"))))) -> HEALTHY | V14: 9 | Z14: =IF($X14="","",ROUND($X14/Summary!$B$3*100,1)) | AA14: =IF($X14="","",IF($X14<2,"LETHAL",IF($X14<4,"CRITICAL",IF($X14<5,"LOW",IF($X14<=8,"HEALTHY","SUPERSAT")))))
A15: 10 | B15: 3:00 | C15: 3.5 | E15: =IF($C15="","",ROUND($C15/Summary!$B$3*100,1)) -> 25.9 | F15: =IF($C15="","",IF($C15<2,"LETHAL",IF($C15<4,"CRITICAL",IF($C15<5,"LOW",IF($C15<=8,"HEALTHY","SUPERSAT"))))) -> CRITICAL | H15: 10 | I15: 0:45 | J15: 5.7 | L15: =IF($J15="","",ROUND($J15/Summary!$B$3*100,1)) -> 42.2 | M15: =IF($J15="","",IF($J15<2,"LETHAL",IF($J15<4,"CRITICAL",IF($J15<5,"LOW",IF($J15<=8,"HEALTHY","SUPERSAT"))))) -> HEALTHY | O15: 10 | P15: 4:00 PM | Q15: 5.5 | S15: =IF($Q15="","",ROUND($Q15/Summary!$B$3*100,1)) -> 40.7 | T15: =IF($Q15="","",IF($Q15<2,"LETHAL",IF($Q15<4,"CRITICAL",IF($Q15<5,"LOW",IF($Q15<=8,"HEALTHY","SUPERSAT"))))) -> HEALTHY | V15: 10 | Z15: =IF($X15="","",ROUND($X15/Summary!$B$3*100,1)) | AA15: =IF($X15="","",IF($X15<2,"LETHAL",IF($X15<4,"CRITICAL",IF($X15<5,"LOW",IF($X15<=8,"HEALTHY","SUPERSAT")))))
A16: 11 | B16: 3:20 | C16: 3.5 | E16: =IF($C16="","",ROUND($C16/Summary!$B$3*100,1)) -> 25.9 | F16: =IF($C16="","",IF($C16<2,"LETHAL",IF($C16<4,"CRITICAL",IF($C16<5,"LOW",IF($C16<=8,"HEALTHY","SUPERSAT"))))) -> CRITICAL | H16: 11 | I16: 0:50 | J16: 5.7 | L16: =IF($J16="","",ROUND($J16/Summary!$B$3*100,1)) -> 42.2 | M16: =IF($J16="","",IF($J16<2,"LETHAL",IF($J16<4,"CRITICAL",IF($J16<5,"LOW",IF($J16<=8,"HEALTHY","SUPERSAT"))))) -> HEALTHY | O16: 11 | P16: 5:00 PM | Q16: 5.4 | S16: =IF($Q16="","",ROUND($Q16/Summary!$B$3*100,1)) -> 40 | T16: =IF($Q16="","",IF($Q16<2,"LETHAL",IF($Q16<4,"CRITICAL",IF($Q16<5,"LOW",IF($Q16<=8,"HEALTHY","SUPERSAT"))))) -> HEALTHY | V16: 11 | Z16: =IF($X16="","",ROUND($X16/Summary!$B$3*100,1)) | AA16: =IF($X16="","",IF($X16<2,"LETHAL",IF($X16<4,"CRITICAL",IF($X16<5,"LOW",IF($X16<=8,"HEALTHY","SUPERSAT")))))
A17: 12 | B17: 3:40 | C17: 3.7 | E17: =IF($C17="","",ROUND($C17/Summary!$B$3*100,1)) -> 27.4 | F17: =IF($C17="","",IF($C17<2,"LETHAL",IF($C17<4,"CRITICAL",IF($C17<5,"LOW",IF($C17<=8,"HEALTHY","SUPERSAT"))))) -> CRITICAL | H17: 12 | I17: 0:55 | J17: 5.8 | L17: =IF($J17="","",ROUND($J17/Summary!$B$3*100,1)) -> 43 | M17: =IF($J17="","",IF($J17<2,"LETHAL",IF($J17<4,"CRITICAL",IF($J17<5,"LOW",IF($J17<=8,"HEALTHY","SUPERSAT"))))) -> HEALTHY | V17: 12 | Z17: =IF($X17="","",ROUND($X17/Summary!$B$3*100,1)) | AA17: =IF($X17="","",IF($X17<2,"LETHAL",IF($X17<4,"CRITICAL",IF($X17<5,"LOW",IF($X17<=8,"HEALTHY","SUPERSAT")))))
A18: 13 | B18: 4:00 | C18: 3.6 | E18: =IF($C18="","",ROUND($C18/Summary!$B$3*100,1)) -> 26.7 | F18: =IF($C18="","",IF($C18<2,"LETHAL",IF($C18<4,"CRITICAL",IF($C18<5,"LOW",IF($C18<=8,"HEALTHY","SUPERSAT"))))) -> CRITICAL | H18: 13 | I18: 1:00 | J18: 5.5 | L18: =IF($J18="","",ROUND($J18/Summary!$B$3*100,1)) -> 40.7 | M18: =IF($J18="","",IF($J18<2,"LETHAL",IF($J18<4,"CRITICAL",IF($J18<5,"LOW",IF($J18<=8,"HEALTHY","SUPERSAT"))))) -> HEALTHY | O18: STATISTICS | V18: 13 | Z18: =IF($X18="","",ROUND($X18/Summary!$B$3*100,1)) | AA18: =IF($X18="","",IF($X18<2,"LETHAL",IF($X18<4,"CRITICAL",IF($X18<5,"LOW",IF($X18<=8,"HEALTHY","SUPERSAT")))))
A19: 14 | B19: 4:20 | C19: 3.5 | E19: =IF($C19="","",ROUND($C19/Summary!$B$3*100,1)) -> 25.9 | F19: =IF($C19="","",IF($C19<2,"LETHAL",IF($C19<4,"CRITICAL",IF($C19<5,"LOW",IF($C19<=8,"HEALTHY","SUPERSAT"))))) -> CRITICAL | H19: 14 | I19: 1:05 | J19: 5.5 | L19: =IF($J19="","",ROUND($J19/Summary!$B$3*100,1)) -> 40.7 | M19: =IF($J19="","",IF($J19<2,"LETHAL",IF($J19<4,"CRITICAL",IF($J19<5,"LOW",IF($J19<=8,"HEALTHY","SUPERSAT"))))) -> HEALTHY | P19: Readings | Q19: =COUNT(Q6:Q16) -> 11 | V19: 14 | Z19: =IF($X19="","",ROUND($X19/Summary!$B$3*100,1)) | AA19: =IF($X19="","",IF($X19<2,"LETHAL",IF($X19<4,"CRITICAL",IF($X19<5,"LOW",IF($X19<=8,"HEALTHY","SUPERSAT")))))
A20: 15 | B20: 4:40 | C20: 3.5 | E20: =IF($C20="","",ROUND($C20/Summary!$B$3*100,1)) -> 25.9 | F20: =IF($C20="","",IF($C20<2,"LETHAL",IF($C20<4,"CRITICAL",IF($C20<5,"LOW",IF($C20<=8,"HEALTHY","SUPERSAT"))))) -> CRITICAL | H20: 15 | I20: 1:10 | J20: 5.5 | L20: =IF($J20="","",ROUND($J20/Summary!$B$3*100,1)) -> 40.7 | M20: =IF($J20="","",IF($J20<2,"LETHAL",IF($J20<4,"CRITICAL",IF($J20<5,"LOW",IF($J20<=8,"HEALTHY","SUPERSAT"))))) -> HEALTHY | P20: Mean | Q20: =IFERROR(AVERAGE(Q6:Q16),"") -> 5.3 | V20: 15 | Z20: =IF($X20="","",ROUND($X20/Summary!$B$3*100,1)) | AA20: =IF($X20="","",IF($X20<2,"LETHAL",IF($X20<4,"CRITICAL",IF($X20<5,"LOW",IF($X20<=8,"HEALTHY","SUPERSAT")))))
A21: 16 | B21: 5:00 | C21: 3.5 | E21: =IF($C21="","",ROUND($C21/Summary!$B$3*100,1)) -> 25.9 | F21: =IF($C21="","",IF($C21<2,"LETHAL",IF($C21<4,"CRITICAL",IF($C21<5,"LOW",IF($C21<=8,"HEALTHY","SUPERSAT"))))) -> CRITICAL | H21: 16 | I21: 1:15 | J21: 5.7 | L21: =IF($J21="","",ROUND($J21/Summary!$B$3*100,1)) -> 42.2 | M21: =IF($J21="","",IF($J21<2,"LETHAL",IF($J21<4,"CRITICAL",IF($J21<5,"LOW",IF($J21<=8,"HEALTHY","SUPERSAT"))))) -> HEALTHY | P21: Std dev | Q21: =IFERROR(_xludf.STDEV.S(Q6:Q16),"") | V21: 16 | Z21: =IF($X21="","",ROUND($X21/Summary!$B$3*100,1)) | AA21: =IF($X21="","",IF($X21<2,"LETHAL",IF($X21<4,"CRITICAL",IF($X21<5,"LOW",IF($X21<=8,"HEALTHY","SUPERSAT")))))
A22: 17 | B22: 5:20 | C22: 3.4 | E22: =IF($C22="","",ROUND($C22/Summary!$B$3*100,1)) -> 25.2 | F22: =IF($C22="","",IF($C22<2,"LETHAL",IF($C22<4,"CRITICAL",IF($C22<5,"LOW",IF($C22<=8,"HEALTHY","SUPERSAT"))))) -> CRITICAL | H22: 17 | I22: 1:20 | J22: 5.5 | L22: =IF($J22="","",ROUND($J22/Summary!$B$3*100,1)) -> 40.7 | M22: =IF($J22="","",IF($J22<2,"LETHAL",IF($J22<4,"CRITICAL",IF($J22<5,"LOW",IF($J22<=8,"HEALTHY","SUPERSAT"))))) -> HEALTHY | P22: Minimum | Q22: =IFERROR(MIN(Q6:Q16),"") -> 3.3 | V22: 17 | Z22: =IF($X22="","",ROUND($X22/Summary!$B$3*100,1)) | AA22: =IF($X22="","",IF($X22<2,"LETHAL",IF($X22<4,"CRITICAL",IF($X22<5,"LOW",IF($X22<=8,"HEALTHY","SUPERSAT")))))
A23: 18 | B23: 5:40 | C23: 4.3 | E23: =IF($C23="","",ROUND($C23/Summary!$B$3*100,1)) -> 31.9 | F23: =IF($C23="","",IF($C23<2,"LETHAL",IF($C23<4,"CRITICAL",IF($C23<5,"LOW",IF($C23<=8,"HEALTHY","SUPERSAT"))))) -> LOW | H23: 18 | I23: 1:25 | J23: 5.6 | L23: =IF($J23="","",ROUND($J23/Summary!$B$3*100,1)) -> 41.5 | M23: =IF($J23="","",IF($J23<2,"LETHAL",IF($J23<4,"CRITICAL",IF($J23<5,"LOW",IF($J23<=8,"HEALTHY","SUPERSAT"))))) -> HEALTHY | P23: Maximum | Q23: =IFERROR(MAX(Q6:Q16),"") -> 5.8 | V23: 18 | Z23: =IF($X23="","",ROUND($X23/Summary!$B$3*100,1)) | AA23: =IF($X23="","",IF($X23<2,"LETHAL",IF($X23<4,"CRITICAL",IF($X23<5,"LOW",IF($X23<=8,"HEALTHY","SUPERSAT")))))
A24: 19 | B24: 6:00 | C24: 4.3 | E24: =IF($C24="","",ROUND($C24/Summary!$B$3*100,1)) -> 31.9 | F24: =IF($C24="","",IF($C24<2,"LETHAL",IF($C24<4,"CRITICAL",IF($C24<5,"LOW",IF($C24<=8,"HEALTHY","SUPERSAT"))))) -> LOW | H24: 19 | I24: 1:30 | J24: 5.5 | L24: =IF($J24="","",ROUND($J24/Summary!$B$3*100,1)) -> 40.7 | M24: =IF($J24="","",IF($J24<2,"LETHAL",IF($J24<4,"CRITICAL",IF($J24<5,"LOW",IF($J24<=8,"HEALTHY","SUPERSAT"))))) -> HEALTHY | P24: Range | Q24: =IF(COUNT(Q6:Q16)=0,"",MAX(Q6:Q16)-MIN(Q6:Q16)) -> 2.5 | V24: 19 | Z24: =IF($X24="","",ROUND($X24/Summary!$B$3*100,1)) | AA24: =IF($X24="","",IF($X24<2,"LETHAL",IF($X24<4,"CRITICAL",IF($X24<5,"LOW",IF($X24<=8,"HEALTHY","SUPERSAT")))))
A25: 20 | B25: 6:20 | C25: 4.3 | E25: =IF($C25="","",ROUND($C25/Summary!$B$3*100,1)) -> 31.9 | F25: =IF($C25="","",IF($C25<2,"LETHAL",IF($C25<4,"CRITICAL",IF($C25<5,"LOW",IF($C25<=8,"HEALTHY","SUPERSAT"))))) -> LOW | H25: 20 | I25: 1:35 | J25: 5.4 | L25: =IF($J25="","",ROUND($J25/Summary!$B$3*100,1)) -> 40 | M25: =IF($J25="","",IF($J25<2,"LETHAL",IF($J25<4,"CRITICAL",IF($J25<5,"LOW",IF($J25<=8,"HEALTHY","SUPERSAT"))))) -> HEALTHY | P25: Mean % sat | Q25: =IFERROR(AVERAGE(S6:S16),"") -> 39.254545 | V25: 20 | Z25: =IF($X25="","",ROUND($X25/Summary!$B$3*100,1)) | AA25: =IF($X25="","",IF($X25<2,"LETHAL",IF($X25<4,"CRITICAL",IF($X25<5,"LOW",IF($X25<=8,"HEALTHY","SUPERSAT")))))
A26: 21 | B26: 6:40 | C26: 4.4 | E26: =IF($C26="","",ROUND($C26/Summary!$B$3*100,1)) -> 32.6 | F26: =IF($C26="","",IF($C26<2,"LETHAL",IF($C26<4,"CRITICAL",IF($C26<5,"LOW",IF($C26<=8,"HEALTHY","SUPERSAT"))))) -> LOW | H26: 21 | I26: 1:40 | J26: 5.8 | L26: =IF($J26="","",ROUND($J26/Summary!$B$3*100,1)) -> 43 | M26: =IF($J26="","",IF($J26<2,"LETHAL",IF($J26<4,"CRITICAL",IF($J26<5,"LOW",IF($J26<=8,"HEALTHY","SUPERSAT"))))) -> HEALTHY | V26: 21 | Z26: =IF($X26="","",ROUND($X26/Summary!$B$3*100,1)) | AA26: =IF($X26="","",IF($X26<2,"LETHAL",IF($X26<4,"CRITICAL",IF($X26<5,"LOW",IF($X26<=8,"HEALTHY","SUPERSAT")))))
A27: 22 | B27: 7:00 | C27: 4.5 | E27: =IF($C27="","",ROUND($C27/Summary!$B$3*100,1)) -> 33.3 | F27: =IF($C27="","",IF($C27<2,"LETHAL",IF($C27<4,"CRITICAL",IF($C27<5,"LOW",IF($C27<=8,"HEALTHY","SUPERSAT"))))) -> LOW | H27: 22 | I27: 1:45 | J27: 5.8 | L27: =IF($J27="","",ROUND($J27/Summary!$B$3*100,1)) -> 43 | M27: =IF($J27="","",IF($J27<2,"LETHAL",IF($J27<4,"CRITICAL",IF($J27<5,"LOW",IF($J27<=8,"HEALTHY","SUPERSAT"))))) -> HEALTHY | V27: 22 | Z27: =IF($X27="","",ROUND($X27/Summary!$B$3*100,1)) | AA27: =IF($X27="","",IF($X27<2,"LETHAL",IF($X27<4,"CRITICAL",IF($X27<5,"LOW",IF($X27<=8,"HEALTHY","SUPERSAT")))))
A28: 23 | B28: 7:20 | C28: 4.6 | E28: =IF($C28="","",ROUND($C28/Summary!$B$3*100,1)) -> 34.1 | F28: =IF($C28="","",IF($C28<2,"LETHAL",IF($C28<4,"CRITICAL",IF($C28<5,"LOW",IF($C28<=8,"HEALTHY","SUPERSAT"))))) -> LOW | H28: 23 | I28: 1:50 | J28: 5.4 | L28: =IF($J28="","",ROUND($J28/Summary!$B$3*100,1)) -> 40 | M28: =IF($J28="","",IF($J28<2,"LETHAL",IF($J28<4,"CRITICAL",IF($J28<5,"LOW",IF($J28<=8,"HEALTHY","SUPERSAT"))))) -> HEALTHY | V28: 23 | Z28: =IF($X28="","",ROUND($X28/Summary!$B$3*100,1)) | AA28: =IF($X28="","",IF($X28<2,"LETHAL",IF($X28<4,"CRITICAL",IF($X28<5,"LOW",IF($X28<=8,"HEALTHY","SUPERSAT")))))
A29: 24 | B29: 7:40 | C29: 4.5 | E29: =IF($C29="","",ROUND($C29/Summary!$B$3*100,1)) -> 33.3 | F29: =IF($C29="","",IF($C29<2,"LETHAL",IF($C29<4,"CRITICAL",IF($C29<5,"LOW",IF($C29<=8,"HEALTHY","SUPERSAT"))))) -> LOW | H29: 24 | I29: 1:55 | J29: 5.5 | L29: =IF($J29="","",ROUND($J29/Summary!$B$3*100,1)) -> 40.7 | M29: =IF($J29="","",IF($J29<2,"LETHAL",IF($J29<4,"CRITICAL",IF($J29<5,"LOW",IF($J29<=8,"HEALTHY","SUPERSAT"))))) -> HEALTHY | V29: 24 | Z29: =IF($X29="","",ROUND($X29/Summary!$B$3*100,1)) | AA29: =IF($X29="","",IF($X29<2,"LETHAL",IF($X29<4,"CRITICAL",IF($X29<5,"LOW",IF($X29<=8,"HEALTHY","SUPERSAT")))))
A30: 25 | B30: 8:00 | C30: 4.7 | E30: =IF($C30="","",ROUND($C30/Summary!$B$3*100,1)) -> 34.8 | F30: =IF($C30="","",IF($C30<2,"LETHAL",IF($C30<4,"CRITICAL",IF($C30<5,"LOW",IF($C30<=8,"HEALTHY","SUPERSAT"))))) -> LOW | H30: 25 | I30: 2:00 | J30: 5.8 | L30: =IF($J30="","",ROUND($J30/Summary!$B$3*100,1)) -> 43 | M30: =IF($J30="","",IF($J30<2,"LETHAL",IF($J30<4,"CRITICAL",IF($J30<5,"LOW",IF($J30<=8,"HEALTHY","SUPERSAT"))))) -> HEALTHY | V30: 25 | Z30: =IF($X30="","",ROUND($X30/Summary!$B$3*100,1)) | AA30: =IF($X30="","",IF($X30<2,"LETHAL",IF($X30<4,"CRITICAL",IF($X30<5,"LOW",IF($X30<=8,"HEALTHY","SUPERSAT")))))
A31: 26 | B31: 8:20 | C31: 4.8 | E31: =IF($C31="","",ROUND($C31/Summary!$B$3*100,1)) -> 35.6 | F31: =IF($C31="","",IF($C31<2,"LETHAL",IF($C31<4,"CRITICAL",IF($C31<5,"LOW",IF($C31<=8,"HEALTHY","SUPERSAT"))))) -> LOW | H31: 26 | I31: 2:05 | J31: 5.5 | L31: =IF($J31="","",ROUND($J31/Summary!$B$3*100,1)) -> 40.7 | M31: =IF($J31="","",IF($J31<2,"LETHAL",IF($J31<4,"CRITICAL",IF($J31<5,"LOW",IF($J31<=8,"HEALTHY","SUPERSAT"))))) -> HEALTHY | V31: 26 | Z31: =IF($X31="","",ROUND($X31/Summary!$B$3*100,1)) | AA31: =IF($X31="","",IF($X31<2,"LETHAL",IF($X31<4,"CRITICAL",IF($X31<5,"LOW",IF($X31<=8,"HEALTHY","SUPERSAT")))))
A32: 27 | B32: 8:40 | C32: 4.7 | E32: =IF($C32="","",ROUND($C32/Summary!$B$3*100,1)) -> 34.8 | F32: =IF($C32="","",IF($C32<2,"LETHAL",IF($C32<4,"CRITICAL",IF($C32<5,"LOW",IF($C32<=8,"HEALTHY","SUPERSAT"))))) -> LOW | H32: 27 | I32: 2:10 | J32: 5.3 | L32: =IF($J32="","",ROUND($J32/Summary!$B$3*100,1)) -> 39.3 | M32: =IF($J32="","",IF($J32<2,"LETHAL",IF($J32<4,"CRITICAL",IF($J32<5,"LOW",IF($J32<=8,"HEALTHY","SUPERSAT"))))) -> HEALTHY | V32: 27 | Z32: =IF($X32="","",ROUND($X32/Summary!$B$3*100,1)) | AA32: =IF($X32="","",IF($X32<2,"LETHAL",IF($X32<4,"CRITICAL",IF($X32<5,"LOW",IF($X32<=8,"HEALTHY","SUPERSAT")))))
A33: 28 | B33: 9:00 | C33: 4.7 | E33: =IF($C33="","",ROUND($C33/Summary!$B$3*100,1)) -> 34.8 | F33: =IF($C33="","",IF($C33<2,"LETHAL",IF($C33<4,"CRITICAL",IF($C33<5,"LOW",IF($C33<=8,"HEALTHY","SUPERSAT"))))) -> LOW | H33: 28 | I33: 2:15 | J33: 5.2 | L33: =IF($J33="","",ROUND($J33/Summary!$B$3*100,1)) -> 38.5 | M33: =IF($J33="","",IF($J33<2,"LETHAL",IF($J33<4,"CRITICAL",IF($J33<5,"LOW",IF($J33<=8,"HEALTHY","SUPERSAT"))))) -> HEALTHY | V33: 28 | Z33: =IF($X33="","",ROUND($X33/Summary!$B$3*100,1)) | AA33: =IF($X33="","",IF($X33<2,"LETHAL",IF($X33<4,"CRITICAL",IF($X33<5,"LOW",IF($X33<=8,"HEALTHY","SUPERSAT")))))
A34: 29 | B34: 9:20 | C34: 4.8 | E34: =IF($C34="","",ROUND($C34/Summary!$B$3*100,1)) -> 35.6 | F34: =IF($C34="","",IF($C34<2,"LETHAL",IF($C34<4,"CRITICAL",IF($C34<5,"LOW",IF($C34<=8,"HEALTHY","SUPERSAT"))))) -> LOW | H34: 29 | I34: 2:20 | J34: 5.7 | L34: =IF($J34="","",ROUND($J34/Summary!$B$3*100,1)) -> 42.2 | M34: =IF($J34="","",IF($J34<2,"LETHAL",IF($J34<4,"CRITICAL",IF($J34<5,"LOW",IF($J34<=8,"HEALTHY","SUPERSAT"))))) -> HEALTHY | V34: 29 | Z34: =IF($X34="","",ROUND($X34/Summary!$B$3*100,1)) | AA34: =IF($X34="","",IF($X34<2,"LETHAL",IF($X34<4,"CRITICAL",IF($X34<5,"LOW",IF($X34<=8,"HEALTHY","SUPERSAT")))))
A35: 30 | B35: 9:40 | C35: 4.3 | E35: =IF($C35="","",ROUND($C35/Summary!$B$3*100,1)) -> 31.9 | F35: =IF($C35="","",IF($C35<2,"LETHAL",IF($C35<4,"CRITICAL",IF($C35<5,"LOW",IF($C35<=8,"HEALTHY","SUPERSAT"))))) -> LOW | H35: 30 | I35: 2:25 | J35: 5.5 | L35: =IF($J35="","",ROUND($J35/Summary!$B$3*100,1)) -> 40.7 | M35: =IF($J35="","",IF($J35<2,"LETHAL",IF($J35<4,"CRITICAL",IF($J35<5,"LOW",IF($J35<=8,"HEALTHY","SUPERSAT"))))) -> HEALTHY | V35: 30 | Z35: =IF($X35="","",ROUND($X35/Summary!$B$3*100,1)) | AA35: =IF($X35="","",IF($X35<2,"LETHAL",IF($X35<4,"CRITICAL",IF($X35<5,"LOW",IF($X35<=8,"HEALTHY","SUPERSAT")))))
A36: 31 | B36: 10:00 | C36: 4.3 | E36: =IF($C36="","",ROUND($C36/Summary!$B$3*100,1)) -> 31.9 | F36: =IF($C36="","",IF($C36<2,"LETHAL",IF($C36<4,"CRITICAL",IF($C36<5,"LOW",IF($C36<=8,"HEALTHY","SUPERSAT"))))) -> LOW | H36: 31 | I36: 2:30 | J36: 5.5 | L36: =IF($J36="","",ROUND($J36/Summary!$B$3*100,1)) -> 40.7 | M36: =IF($J36="","",IF($J36<2,"LETHAL",IF($J36<4,"CRITICAL",IF($J36<5,"LOW",IF($J36<=8,"HEALTHY","SUPERSAT"))))) -> HEALTHY | V36: 31 | Z36: =IF($X36="","",ROUND($X36/Summary!$B$3*100,1)) | AA36: =IF($X36="","",IF($X36<2,"LETHAL",IF($X36<4,"CRITICAL",IF($X36<5,"LOW",IF($X36<=8,"HEALTHY","SUPERSAT")))))
A37: 32 | B37: 10:20 | C37: 4.5 | E37: =IF($C37="","",ROUND($C37/Summary!$B$3*100,1)) -> 33.3 | F37: =IF($C37="","",IF($C37<2,"LETHAL",IF($C37<4,"CRITICAL",IF($C37<5,"LOW",IF($C37<=8,"HEALTHY","SUPERSAT"))))) -> LOW | H37: 32 | I37: 2:35 | J37: 5.8 | L37: =IF($J37="","",ROUND($J37/Summary!$B$3*100,1)) -> 43 | M37: =IF($J37="","",IF($J37<2,"LETHAL",IF($J37<4,"CRITICAL",IF($J37<5,"LOW",IF($J37<=8,"HEALTHY","SUPERSAT"))))) -> HEALTHY | V37: 32 | Z37: =IF($X37="","",ROUND($X37/Summary!$B$3*100,1)) | AA37: =IF($X37="","",IF($X37<2,"LETHAL",IF($X37<4,"CRITICAL",IF($X37<5,"LOW",IF($X37<=8,"HEALTHY","SUPERSAT")))))
... A55: 50 | B55: 16:20 | C55: 5.6 | E55: =IF($C55="","",ROUND($C55/Summary!$B$3*100,1)) -> 41.5 | F55: =IF($C55="","",IF($C55<2,"LETHAL",IF($C55<4,"CRITICAL",IF($C55<5,"LOW",IF($C55<=8,"HEALTHY","SUPERSAT"))))) -> HEALTHY | H55: 50 | I55: 4:05 | J55: 5.4 | L55: =IF($J55="","",ROUND($J55/Summary!$B$3*100,1)) -> 40 | M55: =IF($J55="","",IF($J55<2,"LETHAL",IF($J55<4,"CRITICAL",IF($J55<5,"LOW",IF($J55<=8,"HEALTHY","SUPERSAT"))))) -> HEALTHY | V55: 50 | Z55: =IF($X55="","",ROUND($X55/Summary!$B$3*100,1)) | AA55: =IF($X55="","",IF($X55<2,"LETHAL",IF($X55<4,"CRITICAL",IF($X55<5,"LOW",IF($X55<=8,"HEALTHY","SUPERSAT")))))
A57: STATISTICS | V57: STATISTICS
B58: Readings | C58: =COUNT(C6:C55) -> 50 | I58: Readings | J58: =COUNT(J6:J55) -> 50 | W58: Readings | X58: =COUNT(X6:X55) -> 0
...

Sheet Day 3
A1: DISSOLVED OXYGEN LOG - DAY 3
A2: Date: | B2: 11.14.16 | C2: Weather: | D2: Sunny | H2: Recorded by: | O2: Location: | V2: Reference: | W2: =Summary!$B$3 -> 13.5
D3: Rained Last night/New Water added
A4: A. EVERY 20 SECONDS | H4: B. EVERY 5 MINUTES | O4: C. HOURLY 7AM-5PM | V4: D. CUSTOM
A5: # | B5: Elapsed | C5: DO mg/L | E5: % Sat | F5: Status | H5: # | I5: Elapsed | J5: DO mg/L | L5: % Sat | M5: Status | O5: # | P5: Time | Q5: DO mg/L | S5: % Sat | T5: Status | V5: # | W5: Time | X5: DO mg/L | Z5: % Sat | AA5: Status
A6: 1 | B6: 0:00 | C6: 5.1 | E6: =IF($C6="","",ROUND($C6/Summary!$B$3*100,1)) -> 37.8 | F6: =IF($C6="","",IF($C6<2,"LETHAL",IF($C6<4,"CRITICAL",IF($C6<5,"LOW",IF($C6<=8,"HEALTHY","SUPERSAT"))))) -> HEALTHY | H6: 1 | I6: 0:00 | J6: 5.1 | L6: =IF($J6="","",ROUND($J6/Summary!$B$3*100,1)) -> 37.8 | M6: =IF($J6="","",IF($J6<2,"LETHAL",IF($J6<4,"CRITICAL",IF($J6<5,"LOW",IF($J6<=8,"HEALTHY","SUPERSAT"))))) -> HEALTHY | O6: 1 | P6: 7:00 AM | Q6: 5.1 | S6: =IF($Q6="","",ROUND($Q6/Summary!$B$3*100,1)) -> 37.8 | T6: =IF($Q6="","",IF($Q6<2,"LETHAL",IF($Q6<4,"CRITICAL",IF($Q6<5,"LOW",IF($Q6<=8,"HEALTHY","SUPERSAT"))))) -> HEALTHY | V6: 1 | Z6: =IF($X6="","",ROUND($X6/Summary!$B$3*100,1)) | AA6: =IF($X6="","",IF($X6<2,"LETHAL",IF($X6<4,"CRITICAL",IF($X6<5,"LOW",IF($X6<=8,"HEALTHY","SUPERSAT")))))
A7: 2 | B7: 0:20 | C7: 5.3 | E7: =IF($C7="","",ROUND($C7/Summary!$B$3*100,1)) -> 39.3 | F7: =IF($C7="","",IF($C7<2,"LETHAL",IF($C7<4,"CRITICAL",IF($C7<5,"LOW",IF($C7<=8,"HEALTHY","SUPERSAT"))))) -> HEALTHY | H7: 2 | I7: 0:05 | J7: 5.5 | L7: =IF($J7="","",ROUND($J7/Summary!$B$3*100,1)) -> 40.7 | M7: =IF($J7="","",IF($J7<2,"LETHAL",IF($J7<4,"CRITICAL",IF($J7<5,"LOW",IF($J7<=8,"HEALTHY","SUPERSAT"))))) -> HEALTHY | O7: 2 | P7: 8:00 AM | Q7: 5.7 | S7: =IF($Q7="","",ROUND($Q7/Summary!$B$3*100,1)) -> 42.2 | T7: =IF($Q7="","",IF($Q7<2,"LETHAL",IF($Q7<4,"CRITICAL",IF($Q7<5,"LOW",IF($Q7<=8,"HEALTHY","SUPERSAT"))))) -> HEALTHY | V7: 2 | Z7: =IF($X7="","",ROUND($X7/Summary!$B$3*100,1)) | AA7: =IF($X7="","",IF($X7<2,"LETHAL",IF($X7<4,"CRITICAL",IF($X7<5,"LOW",IF($X7<=8,"HEALTHY","SUPERSAT")))))
A8: 3 | B8: 0:40 | C8: 5.5 | E8: =IF($C8="","",ROUND($C8/Summary!$B$3*100,1)) -> 40.7 | F8: =IF($C8="","",IF($C8<2,"LETHAL",IF($C8<4,"CRITICAL",IF($C8<5,"LOW",IF($C8<=8,"HEALTHY","SUPERSAT"))))) -> HEALTHY | H8: 3 | I8: 0:10 | J8: 5.8 | L8: =IF($J8="","",ROUND($J8/Summary!$B$3*100,1)) -> 43 | M8: =IF($J8="","",IF($J8<2,"LETHAL",IF($J8<4,"CRITICAL",IF($J8<5,"LOW",IF($J8<=8,"HEALTHY","SUPERSAT"))))) -> HEALTHY | O8: 3 | P8: 9:00 AM | Q8: 5.5 | S8: =IF($Q8="","",ROUND($Q8/Summary!$B$3*100,1)) -> 40.7 | T8: =IF($Q8="","",IF($Q8<2,"LETHAL",IF($Q8<4,"CRITICAL",IF($Q8<5,"LOW",IF($Q8<=8,"HEALTHY","SUPERSAT"))))) -> HEALTHY | V8: 3 | Z8: =IF($X8="","",ROUND($X8/Summary!$B$3*100,1)) | AA8: =IF($X8="","",IF($X8<2,"LETHAL",IF($X8<4,"CRITICAL",IF($X8<5,"LOW",IF($X8<=8,"HEALTHY","SUPERSAT")))))
A9: 4 | B9: 1:00 | C9: 5.4 | E9: =IF($C9="","",ROUND($C9/Summary!$B$3*100,1)) -> 40 | F9: =IF($C9="","",IF($C9<2,"LETHAL",IF($C9<4,"CRITICAL",IF($C9<5,"LOW",IF($C9<=8,"HEALTHY","SUPERSAT"))))) -> HEALTHY | H9: 4 | I9: 0:15 | J9: 5.7 | L9: =IF($J9="","",ROUND($J9/Summary!$B$3*100,1)) -> 42.2 | M9: =IF($J9="","",IF($J9<2,"LETHAL",IF($J9<4,"CRITICAL",IF($J9<5,"LOW",IF($J9<=8,"HEALTHY","SUPERSAT"))))) -> HEALTHY | O9: 4 | P9: 10:00 AM | Q9: 5.5 | S9: =IF($Q9="","",ROUND($Q9/Summary!$B$3*100,1)) -> 40.7 | T9: =IF($Q9="","",IF($Q9<2,"LETHAL",IF($Q9<4,"CRITICAL",IF($Q9<5,"LOW",IF($Q9<=8,"HEALTHY","SUPERSAT"))))) -> HEALTHY | V9: 4 | Z9: =IF($X9="","",ROUND($X9/Summary!$B$3*100,1)) | AA9: =IF($X9="","",IF($X9<2,"LETHAL",IF($X9<4,"CRITICAL",IF($X9<5,"LOW",IF($X9<=8,"HEALTHY","SUPERSAT")))))
A10: 5 | B10: 1:20 | C10: 5.5 | E10: =IF($C10="","",ROUND($C10/Summary!$B$3*100,1)) -> 40.7 | F10: =IF($C10="","",IF($C10<2,"LETHAL",IF($C10<4,"CRITICAL",IF($C10<5,"LOW",IF($C10<=8,"HEALTHY","SUPERSAT"))))) -> HEALTHY | H10: 5 | I10: 0:20 | J10: 5.7 | L10: =IF($J10="","",ROUND($J10/Summary!$B$3*100,1)) -> 42.2 | M10: =IF($J10="","",IF($J10<2,"LETHAL",IF($J10<4,"CRITICAL",IF($J10<5,"LOW",IF($J10<=8,"HEALTHY","SUPERSAT"))))) -> HEALTHY | O10: 5 | P10: 11:00 AM | Q10: 6.5 | S10: =IF($Q10="","",ROUND($Q10/Summary!$B$3*100,1)) -> 48.1 | T10: =IF($Q10="","",IF($Q10<2,"LETHAL",IF($Q10<4,"CRITICAL",IF($Q10<5,"LOW",IF($Q10<=8,"HEALTHY","SUPERSAT"))))) -> HEALTHY | V10: 5 | Z10: =IF($X10="","",ROUND($X10/Summary!$B$3*100,1)) | AA10: =IF($X10="","",IF($X10<2,"LETHAL",IF($X10<4,"CRITICAL",IF($X10<5,"LOW",IF($X10<=8,"HEALTHY","SUPERSAT")))))
A11: 6 | B11: 1:40 | C11: 5.5 | E11: =IF($C11="","",ROUND($C11/Summary!$B$3*100,1)) -> 40.7 | F11: =IF($C11="","",IF($C11<2,"LETHAL",IF($C11<4,"CRITICAL",IF($C11<5,"LOW",IF($C11<=8,"HEALTHY","SUPERSAT"))))) -> HEALTHY | H11: 6 | I11: 0:25 | J11: 5.4 | L11: =IF($J11="","",ROUND($J11/Summary!$B$3*100,1)) -> 40 | M11: =IF($J11="","",IF($J11<2,"LETHAL",IF($J11<4,"CRITICAL",IF($J11<5,"LOW",IF($J11<=8,"HEALTHY","SUPERSAT"))))) -> HEALTHY | O11: 6 | P11: 12:00 NN | Q11: 7.2 | S11: =IF($Q11="","",ROUND($Q11/Summary!$B$3*100,1)) -> 53.3 | T11: =IF($Q11="","",IF($Q11<2,"LETHAL",IF($Q11<4,"CRITICAL",IF($Q11<5,"LOW",IF($Q11<=8,"HEALTHY","SUPERSAT"))))) -> HEALTHY | V11: 6 | Z11: =IF($X11="","",ROUND($X11/Summary!$B$3*100,1)) | AA11: =IF($X11="","",IF($X11<2,"LETHAL",IF($X11<4,"CRITICAL",IF($X11<5,"LOW",IF($X11<=8,"HEALTHY","SUPERSAT")))))
A12: 7 | B12: 2:00 | C12: 5.7 | E12: =IF($C12="","",ROUND($C12/Summary!$B$3*100,1)) -> 42.2 | F12: =IF($C12="","",IF($C12<2,"LETHAL",IF($C12<4,"CRITICAL",IF($C12<5,"LOW",IF($C12<=8,"HEALTHY","SUPERSAT"))))) -> HEALTHY | H12: 7 | I12: 0:30 | J12: 5.9 | L12: =IF($J12="","",ROUND($J12/Summary!$B$3*100,1)) -> 43.7 | M12: =IF($J12="","",IF($J12<2,"LETHAL",IF($J12<4,"CRITICAL",IF($J12<5,"LOW",IF($J12<=8,"HEALTHY","SUPERSAT"))))) -> HEALTHY | O12: 7 | P12: 1:00 PM | Q12: 7.4 | S12: =IF($Q12="","",ROUND($Q12/Summary!$B$3*100,1)) -> 54.8 | T12: =IF($Q12="","",IF($Q12<2,"LETHAL",IF($Q12<4,"CRITICAL",IF($Q12<5,"LOW",IF($Q12<=8,"HEALTHY","SUPERSAT"))))) -> HEALTHY | V12: 7 | Z12: =IF($X12="","",ROUND($X12/Summary!$B$3*100,1)) | AA12: =IF($X12="","",IF($X12<2,"LETHAL",IF($X12<4,"CRITICAL",IF($X12<5,"LOW",IF($X12<=8,"HEALTHY","SUPERSAT")))))
A13: 8 | B13: 2:20 | C13: 5.5 | E13: =IF($C13="","",ROUND($C13/Summary!$B$3*100,1)) -> 40.7 | F13: =IF($C13="","",IF($C13<2,"LETHAL",IF($C13<4,"CRITICAL",IF($C13<5,"LOW",IF($C13<=8,"HEALTHY","SUPERSAT"))))) -> HEALTHY | H13: 8 | I13: 0:35 | J13: 5.8 | L13: =IF($J13="","",ROUND($J13/Summary!$B$3*100,1)) -> 43 | M13: =IF($J13="","",IF($J13<2,"LETHAL",IF($J13<4,"CRITICAL",IF($J13<5,"LOW",IF($J13<=8,"HEALTHY","SUPERSAT"))))) -> HEALTHY | O13: 8 | P13: 2:00 PM | Q13: 8.4 | S13: =IF($Q13="","",ROUND($Q13/Summary!$B$3*100,1)) -> 62.2 | T13: =IF($Q13="","",IF($Q13<2,"LETHAL",IF($Q13<4,"CRITICAL",IF($Q13<5,"LOW",IF($Q13<=8,"HEALTHY","SUPERSAT"))))) -> SUPERSAT | V13: 8 | Z13: =IF($X13="","",ROUND($X13/Summary!$B$3*100,1)) | AA13: =IF($X13="","",IF($X13<2,"LETHAL",IF($X13<4,"CRITICAL",IF($X13<5,"LOW",IF($X13<=8,"HEALTHY","SUPERSAT")))))
A14: 9 | B14: 2:40 | C14: 5.5 | E14: =IF($C14="","",ROUND($C14/Summary!$B$3*100,1)) -> 40.7 | F14: =IF($C14="","",IF($C14<2,"LETHAL",IF($C14<4,"CRITICAL",IF($C14<5,"LOW",IF($C14<=8,"HEALTHY","SUPERSAT"))))) -> HEALTHY | H14: 9 | I14: 0:40 | J14: 5.8 | L14: =IF($J14="","",ROUND($J14/Summary!$B$3*100,1)) -> 43 | M14: =IF($J14="","",IF($J14<2,"LETHAL",IF($J14<4,"CRITICAL",IF($J14<5,"LOW",IF($J14<=8,"HEALTHY","SUPERSAT"))))) -> HEALTHY | O14: 9 | P14: 3:00 PM | Q14: 10.2 | S14: =IF($Q14="","",ROUND($Q14/Summary!$B$3*100,1)) -> 75.6 | T14: =IF($Q14="","",IF($Q14<2,"LETHAL",IF($Q14<4,"CRITICAL",IF($Q14<5,"LOW",IF($Q14<=8,"HEALTHY","SUPERSAT"))))) -> SUPERSAT | V14: 9 | Z14: =IF($X14="","",ROUND($X14/Summary!$B$3*100,1)) | AA14: =IF($X14="","",IF($X14<2,"LETHAL",IF($X14<4,"CRITICAL",IF($X14<5,"LOW",IF($X14<=8,"HEALTHY","SUPERSAT")))))
A15: 10 | B15: 3:00 | C15: 5.3 | E15: =IF($C15="","",ROUND($C15/Summary!$B$3*100,1)) -> 39.3 | F15: =IF($C15="","",IF($C15<2,"LETHAL",IF($C15<4,"CRITICAL",IF($C15<5,"LOW",IF($C15<=8,"HEALTHY","SUPERSAT"))))) -> HEALTHY | H15: 10 | I15: 0:45 | J15: 5.7 | L15: =IF($J15="","",ROUND($J15/Summary!$B$3*100,1)) -> 42.2 | M15: =IF($J15="","",IF($J15<2,"LETHAL",IF($J15<4,"CRITICAL",IF($J15<5,"LOW",IF($J15<=8,"HEALTHY","SUPERSAT"))))) -> HEALTHY | O15: 10 | P15: 4:00 PM | Q15: 9.3 | S15: =IF($Q15="","",ROUND($Q15/Summary!$B$3*100,1)) -> 68.9 | T15: =IF($Q15="","",IF($Q15<2,"LETHAL",IF($Q15<4,"CRITICAL",IF($Q15<5,"LOW",IF($Q15<=8,"HEALTHY","SUPERSAT"))))) -> SUPERSAT | V15: 10 | Z15: =IF($X15="","",ROUND($X15/Summary!$B$3*100,1)) | AA15: =IF($X15="","",IF($X15<2,"LETHAL",IF($X15<4,"CRITICAL",IF($X15<5,"LOW",IF($X15<=8,"HEALTHY","SUPERSAT")))))
A16: 11 | B16: 3:20 | C16: 5.5 | E16: =IF($C16="","",ROUND($C16/Summary!$B$3*100,1)) -> 40.7 | F16: =IF($C16="","",IF($C16<2,"LETHAL",IF($C16<4,"CRITICAL",IF($C16<5,"LOW",IF($C16<=8,"HEALTHY","SUPERSAT"))))) -> HEALTHY | H16: 11 | I16: 0:50 | J16: 5.7 | L16: =IF($J16="","",ROUND($J16/Summary!$B$3*100,1)) -> 42.2 | M16: =IF($J16="","",IF($J16<2,"LETHAL",IF($J16<4,"CRITICAL",IF($J16<5,"LOW",IF($J16<=8,"HEALTHY","SUPERSAT"))))) -> HEALTHY | O16: 11 | P16: 5:00 PM | Q16: 8.3 | S16: =IF($Q16="","",ROUND($Q16/Summary!$B$3*100,1)) -> 61.5 | T16: =IF($Q16="","",IF($Q16<2,"LETHAL",IF($Q16<4,"CRITICAL",IF($Q16<5,"LOW",IF($Q16<=8,"HEALTHY","SUPERSAT"))))) -> SUPERSAT | V16: 11 | Z16: =IF($X16="","",ROUND($X16/Summary!$B$3*100,1)) | AA16: =IF($X16="","",IF($X16<2,"LETHAL",IF($X16<4,"CRITICAL",IF($X16<5,"LOW",IF($X16<=8,"HEALTHY","SUPERSAT")))))
A17: 12 | B17: 3:40 | C17: 5.4 | E17: =IF($C17="","",ROUND($C17/Summary!$B$3*100,1)) -> 40 | F17: =IF($C17="","",IF($C17<2,"LETHAL",IF($C17<4,"CRITICAL",IF($C17<5,"LOW",IF($C17<=8,"HEALTHY","SUPERSAT"))))) -> HEALTHY | H17: 12 | I17: 0:55 | J17: 5.4 | L17: =IF($J17="","",ROUND($J17/Summary!$B$3*100,1)) -> 40 | M17: =IF($J17="","",IF($J17<2,"LETHAL",IF($J17<4,"CRITICAL",IF($J17<5,"LOW",IF($J17<=8,"HEALTHY","SUPERSAT"))))) -> HEALTHY | V17: 12 | Z17: =IF($X17="","",ROUND($X17/Summary!$B$3*100,1)) | AA17: =IF($X17="","",IF($X17<2,"LETHAL",IF($X17<4,"CRITICAL",IF($X17<5,"LOW",IF($X17<=8,"HEALTHY","SUPERSAT")))))
A18: 13 | B18: 4:00 | C18: 5.5 | E18: =IF($C18="","",ROUND($C18/Summary!$B$3*100,1)) -> 40.7 | F18: =IF($C18="","",IF($C18<2,"LETHAL",IF($C18<4,"CRITICAL",IF($C18<5,"LOW",IF($C18<=8,"HEALTHY","SUPERSAT"))))) -> HEALTHY | H18: 13 | I18: 1:00 | J18: 5.3 | L18: =IF($J18="","",ROUND($J18/Summary!$B$3*100,1)) -> 39.3 | M18: =IF($J18="","",IF($J18<2,"LETHAL",IF($J18<4,"CRITICAL",IF($J18<5,"LOW",IF($J18<=8,"HEALTHY","SUPERSAT"))))) -> HEALTHY | O18: STATISTICS | V18: 13 | Z18: =IF($X18="","",ROUND($X18/Summary!$B$3*100,1)) | AA18: =IF($X18="","",IF($X18<2,"LETHAL",IF($X18<4,"CRITICAL",IF($X18<5,"LOW",IF($X18<=8,"HEALTHY","SUPERSAT")))))
A19: 14 | B19: 4:20 | C19: 5.6 | E19: =IF($C19="","",ROUND($C19/Summary!$B$3*100,1)) -> 41.5 | F19: =IF($C19="","",IF($C19<2,"LETHAL",IF($C19<4,"CRITICAL",IF($C19<5,"LOW",IF($C19<=8,"HEALTHY","SUPERSAT"))))) -> HEALTHY | H19: 14 | I19: 1:05 | J19: 5.3 | L19: =IF($J19="","",ROUND($J19/Summary!$B$3*100,1)) -> 39.3 | M19: =IF($J19="","",IF($J19<2,"LETHAL",IF($J19<4,"CRITICAL",IF($J19<5,"LOW",IF($J19<=8,"HEALTHY","SUPERSAT"))))) -> HEALTHY | P19: Readings | Q19: =COUNT(Q6:Q16) -> 11 | V19: 14 | Z19: =IF($X19="","",ROUND($X19/Summary!$B$3*100,1)) | AA19: =IF($X19="","",IF($X19<2,"LETHAL",IF($X19<4,"CRITICAL",IF($X19<5,"LOW",IF($X19<=8,"HEALTHY","SUPERSAT")))))
